Workbook

Sheet Projection P&L
A1: Compte de résultat VPRDS | B1: Année 2025 | C1: Année 2026 | D1: Année 2027 | F1: Données marge de production | G1: 2024 | H1: 2025 | I1: 2026 | J1: 2027
A3: Chiffre d'affaires travaux | B3: ='Suivi 31.12.25'!AK62/1000 -> 2424.7343 | C3: =+I19 -> 2686.5571 | D3: =+J19 -> 3097.5 | F3: Nombre de chantiers en cours au 31/12/N-1 réceptionnés en N | G3: =COUNT('Suivi 31.12.2023'!AP3:AP11) -> 8 | H3: 14 | I3: =+H5 -> 14 | J3: =+I5 -> 15 | L3: Ne pas modifier = formules
F4: Nombre de chantiers ouverts et réceptionnés en N | G4: 2 | H4: ='Suivi 31.12.25'!B46 -> 6 | I4: 10 | J4: 10 | L4: A renseigner
F5: Nombre de chantiers encours au 31/12/N | G5: 14 | H5: 14 | I5: 15 | J5: 20
A6: Charges variables sur chantiers | B6: =+B3-B7 -> 1988.5093 | C6: =+C3-C7 -> 2186.933 | D6: =+D3-D7 -> 2478
A7: Marge de production | B7: ='Suivi 31.12.25'!AH62/1000 -> 436.22501 | C7: =+I20 -> 499.62413 | D7: =+J20 -> 619.5 | F7: PV HT moyen (y compris case 0 et net de SASA) chantiers en cours au 31/12/N-1 | G7: =(SUM('SUIVI 31.12.24'!AH29:AH36)/COUNT('SUIVI 31.12.24'!AH29:AH36))/1000 -> 121.94844 | H7: =+G9 -> 120.10867 | I7: =+H9 -> 126.67346 | J7: =+I9 -> 118
A8: % de marge de production | B8: =+B7/B3 -> 0.17990631 | C8: =+C7/C3 -> 0.1859719 | D8: =+D7/D3 -> 0.2 | F8: PV HT moyen (y compris case 0 et net de SASA) chantiers ouverts et réceptionnés en N | G8: =+SUM('SUIVI 31.12.24'!AJ37:AJ38)/'Projection P&L'!G4/1000 -> 114.28727 | H8: =+SUM('Suivi 31.12.25'!AK40:AK45)/'Suivi 31.12.25'!B46/1000 -> 100.42831 | I8: 118 | J8: 118
F9: PV HT moyen (y compris case 0 et net de SASA) chantiers encours au 31/12/N | G9: =(SUM('SUIVI 31.12.24 ALTONEO'!AI3:AI27)/'Projection P&L'!G5)/1000 -> 120.10867 | H9: =+SUM('Suivi 31.12.25'!AI3:AI38)/'Suivi 31.12.25'!B39/1000 -> 126.67346 | I9: 118 | J9: 118
A10: Autres produits (subvention)
F11: Taux de marge moyen chantiers en cours au 31/12/N-1 | G11: =SUM('SUIVI 31.12.24'!AG29:AG36)/SUM('SUIVI 31.12.24'!AJ29:AJ36) -> 0.20165494 | H11: =SUM('Suivi 31.12.25'!AG47:AG60)/SUM('Suivi 31.12.25'!AJ47:AJ60) -> 0.20952266 | I11: =+H13 -> 0.16458152 | J11: =+I13 -> 0.2
A12: Coût de strucutre (masse salariale + charges fixes) | B12: =+B18+B15 -> 414.26811 | C12: =+C18+C15 -> 438.6 | D12: =+D18+D15 -> 526.8 | F12: Taux de marge moyen chantiers ouverts et réceptionnés en N | G12: =+('SUIVI 31.12.24'!AE37+'SUIVI 31.12.24'!AE38)/('SUIVI 31.12.24'!AH37+'SUIVI 31.12.24'!AH38) -> 0.22646675 | H12: =SUM('Suivi 31.12.25'!AF40:AF45)/SUM('Suivi 31.12.25'!AI40:AI45) -> 0.20117384 | I12: 0.2 | J12: 0.2
A13: % du CA | B13: =+B12/(B3) -> 0.17085093 | C13: =+C12/(C3) -> 0.16325728 | D13: =+D12/(D3) -> 0.17007264 | F13: Taux de marge moyen chantiers encours au 31/12/N | G13: =SUM('SUIVI 31.12.24 ALTONEO'!AF3:AF27)/SUM('SUIVI 31.12.24 ALTONEO'!AI3:AI27) -> 0.20283615 | H13: =SUM('Suivi 31.12.25'!AF3:AF38)/SUM('Suivi 31.12.25'!AI3:AI38) -> 0.16458152 | I13: 0.2 | J13: 0.2
A15: Masse salariale (y compris taxes rattachées) | B15: =+H57 -> 214.26811 | C15: =+I57 -> 211.2 | D15: =+J57 -> 276.66 | F15: Taux restant d'avancement des chantiers en cours au 31/12/N-1 à constater en N | G15: =+SUM('SUIVI 31.12.24'!AJ29:AJ36)/SUM('SUIVI 31.12.24'!AH29:AH36) -> 0.70183871 | H15: =(1-G16) -> 0.61863825 | I15: =(1-H16) -> 0.6 | J15: =(1-I16) -> 0.75
B16: =+B15/B3 -> 0.088367664 | C16: =+C15/C3 -> 0.078613628 | D16: =+D15/D3 -> 0.089317191 | F16: Taux d'avancement des chantiers en cours au 31/12/N | G16: =SUMPRODUCT('SUIVI 31.12.24'!E3:E27,'SUIVI 31.12.24'!AH3:AH27)/SUM('SUIVI 31.12.24'!AH3:AH27) -> 0.38136175 | H16: 0.4 | I16: 0.25 | J16: 0.25 | L16: Pour le moment même avancement moyen sur les encours à la fin de chaque année. Peut être modifié à la main ou s'aider des suivi 2025 et années suivantes
A18: Frais généraux | B18: 200 | C18: =SUM(C19:C27) -> 227.4 | D18: =SUM(D19:D27) -> 250.14
A19: Achats non stockés (eau, électricité, fournitures) | B19: 8 | C19: 8.8 | D19: =C19*(1+$J$23) -> 9.68 | F19: Soit un Chiffre d'affaires | G19: =+G3*G7*G15+G5*G9*G16+G4*G8 -> 1554.5476 | H19: =+H3*H7*H15+H5*H9*H16+H4*H8 -> 2352.1947 | I19: =+I3*I7*I15+I5*I9*I16+I4*I8 -> 2686.5571 | J19: =+J3*J7*J15+J5*J9*J16+J4*J8 -> 3097.5
A20: Assurances | B20: 4 | C20: 4.4 | D20: =C20*(1+$J$23) -> 4.84 | F20: Soit une marge de production | G20: =+G3*G7*G15*G11+G4*G8*G12+G5*G9*G13*G16-4 -> 315.91102 | H20: =+H3*H7*H15*H11+H4*H8*H12+H5*H9*H13*H16 -> 455.92738 | I20: =+I3*I7*I15*I11+I4*I8*I12+I5*I9*I13*I16 -> 499.62413 | J20: =+J3*J7*J15*J11+J4*J8*J12+J5*J9*J13*J16 -> 619.5
A21: Maintenance et entretien | B21: 12 | C21: 12 | D21: =C21*(1+$J$23) -> 13.2 | F21: % de marge de production net | G21: =+G20/G19 -> 0.20321734 | H21: =+H20/H19 -> 0.19383063 | I21: =+I20/I19 -> 0.1859719 | J21: =+J20/J19 -> 0.2
A22: Locations immobilières | B22: 20 | C22: 20 | D22: =C22*(1+$J$23) -> 22
A23: Locations mobilières (y compris véhicules) | B23: 20 | C23: 20 | D23: =C23*(1+$J$23) -> 22 | F23: % de variation frais généraux (si baisse mettre - devant le %) versus N-1 | G23: =+(#REF!-#REF!)/#REF! -> #REF! | H23: 0.1 | I23: 0.1 | J23: 0.1
A24: Marketing et Communication (hors redevances de Pub Mikit) | B24: 78 | C24: 80 | D24: =C24*(1+$J$23) -> 88
A25: Honoraires divers | B25: 28 | C25: 30 | D25: =C25*(1+$J$23) -> 33 | F25: Masse salariale (mettre les montants en € et non K€)
A26: Voyages et déplacements (dont carburant) | B26: 50 | C26: 50 | D26: =C26*(1+$J$23) -> 55
A27: Téléphonie, frais postaux et frais bancaires | B27: 2 | C27: 2.2 | D27: =C27*(1+$J$23) -> 2.42 | F27: Salarié 1 salaire Brut mensuel moyen y compris primes | G27: 2800 | H27: 4000 | I27: 5900 | J27: 2800
F28: Salarié 1 montant charges patronales | G28: =G27*0.45 -> 1260 | H28: =H27*0.45 -> 1800 | I28: 0 | J28: =J27*0.45 -> 1260
A29: Autres impôts et taxes | B29: 2 | C29: 3 | D29: 4 | F29: Nombre de mois de présence sur l'année | G29: 4 | H29: 12 | I29: 12 | J29: 12
F30: coûts salarié 1 (VP) | G30: 17090 | H30: 70800 | I30: =+(I27+I28)*I29 -> 70800 | J30: =+(J27+J28)*J29 -> 48720
A31: Amortissements et provisions | B31: 9 | C31: 9 | D31: 9
F32: Salarié 2 salaire Brut mensuel moyen y compris prime | G32: 3200 | H32: 3500 | I32: 5000 | J32: 4200
A33: Résultat d'exploitation | B33: =B7-B12-B29-B31+B10-2 -> 8.9569009 | C33: =C7-C12-C29-C31+C10-2 -> 47.024134 | D33: =D7-D12-D29-D31+D10-2 -> 77.7 | F33: Salarié 2 montant charges patronales | G33: =G32*0.45 -> 1440 | H33: =H32*0.45 -> 1575 | I33: =I32*0.45 -> 2250 | J33: =J32*0.45 -> 1890
F34: Nombre de mois de présence sur l'année | G34: 12 | H34: 12 | I34: 0 | J34: 12
A35: Résultat financier | B35: -2 | C35: -2 | D35: -2 | F35: coûts salarié 2 (AL com) | G35: 51181.47 | H35: 62111.17 | I35: =+(I32+I33)*I34 -> 0 | J35: =+(J32+J33)*J34 -> 73080
A37: Résultat exceptionnel | F37: Salarié 3 salaire Brut mensuel moyen y compris prime | G37: 2500 | H37: 2900 | I37: 3500 | J37: 4200
F38: Salarié 3 montant charges patronales | G38: =G37*0.45 -> 1125 | H38: =H37*0.45 -> 1305 | I38: =I37*0.45 -> 1575 | J38: =J37*0.45 -> 1890
A39: Impôt sur les sociétés | B39: =+B50 -> 0.80966071 | C39: =+C50 -> 7.0060335 | D39: =+D50 -> 14.675 | F39: Nombre de mois de présence sur l'année | G39: 3 | H39: 12 | I39: 12 | J39: 12
F40: coûts salarié 3 (NB com) | G40: 11209.74 | H40: 64522.88 | I40: =+(I37+I38)*I39 -> 60900 | J40: =+(J37+J38)*J39 -> 73080
A41: Résultat net | B41: =+B35+B37-B39+B33 -> 6.1472402 | C41: =+C35+C37-C39+C33 -> 38.018101 | D41: =+D35+D37-D39+D33 -> 61.025
F42: Salarié 4 salaire Brut mensuel moyen y compris pime | H42: 2500 | I42: 3500 | J42: 4700
F43: Salarié 4 montant charges patronales | G43: =G42*0.45 -> 0 | H43: =H42*0.45 -> 1125 | I43: =I42*0.45 -> 1575 | J43: =J42*0.45 -> 2115
F44: Nombre de mois de présence sur l'année | G44: 0 | H44: 6 | I44: 12 | J44: 12
...

Sheet Suivi 2026
F1: Données prévisionnelles ou connues (à mettre à jour) | O1: Factures en compta (à mettre à jour) | U1: cut-off Chiffre d'affaires | Y1: Cut-off charges | AF1: Marges | AI1: Chiffre d'affaires HT | AL1: Frais de dossiers HT | AO1: Reste à comptabiliser | AQ1: % de marge nette | AR1: Solde compte de charges
A2: Étape ↑ | B2: Nom du projet | C2: Facture vente finale faite | D2: Statut chantier | E2: % Avancement | F2: Prix convenu (chiffre d'affaires) HT | G2: Montant avenants HT | H2: Prix actualisé HT net de SASA | I2: SASA dans le projet HT | J2: Redevances Mikit | K2: Redevances Pub | L2: Honoraires MIKIT | M2: Sous-traitance MKT | N2: Honoraires courtage HT | O2: SASA HT | P2: Redevance MIKIT | Q2: Redevance Pub MIKIT | R2: Honoraires MKT | S2: Sous-traitance MKT | T2: Honoraires courtage HT | U2: FAE CA | V2: FAE dossiers assurance | W2: FAE SASA | X2: AAE SASA | Y2: Redevance MIKIT 6% FNP | Z2: Redevance MIKIT CCA | AA2: Redevance pub MIKIT 2.5% FNP | AB2: Redevance pub MIKIT CCA | AC2: Honoraires MIKIT FNP | AD2: Sous-traitance FNP MKT | AE2: Frais courtage CCA | AF2: Marge totale chantier HT | AG2: Marges constatées N-1 | AH2: Marges 2026 HT | AI2: CA Total HT | AJ2: CA constaté N-1 | AK2: CA 2026 HT | AL2: CA Total HT | AM2: CA constaté N-1 | AN2: CA 2024 HT | AO2: CA à comptabiliser € HT | AP2: marge à comptabiliser € HT | AR2: SS MKT | AS2: SS MKT N-1 | AT2: SS MKT N | AU2: Hono MKT | AV2: Hono MKT N-1 | AW2: Hono MKT N | AX2: Fond Mikit | AY2: Fond Mikit N-1 | AZ2: Fond Mikit N | BA2: Pub Mikit | BB2: Pub Mikit N-1 | BC2: Pub Mikit N | BD2: Commissions | BE2: Commissions N-1 | BF2: Commissions N
B3: Projet Beilvert / Voguet Vivoin | C3: non | D3: 1.1 Administratif validé prêt à ouvrir | E3: =VLOOKUP(D3,'% avancement'!$A$4:$B$17,2,FALSE()) -> 0.25 | F3: 125666.67 | G3: 7500 | H3: =F3+G3-I3 -> 128166.67 | I3: 5000 | J3: =(F3+G3-I3)*0.06 -> 7690 | K3: =(F3+G3-I3)*0.025 -> 3204.1667 | L3: 7828.15 | M3: =(F3+G3)*0.62 -> 82563.333 | N3: 6000 | U3: =IF(C3="oui","",(H3+I3)*E3) -> 33291.667 | W3: =IF(O3="",0,(1-E3)*O3) -> 0 | X3: =IF(O3="",I3*(E3),0) -> 1250 | Y3: =IF(P3="",+H3*6%*E3,0) -> 1922.5 | Z3: =IF(P3="",0,P3*(1-E3)) -> 0 | AA3: =IF(Q3="",+H3*2.5%*E3,0) -> 801.04167 | AB3: =IF(Q3="",0,Q3*(1-E3)) -> 0 | AC3: =IF(R3="",+L3*E3,(1-E3)*R3) -> 1957.0375 | AD3: =IF(S3="",M3*E3,S3*E3) -> 20640.833 | AF3: =IF(E3="",0,+H3-J3-K3-L3-M3-N3) -> 20881.017 | AG3: =IFERROR((VLOOKUP(B3,'Suivi 31.12.25'!$B$1:$BF$38,33,FALSE())),0) -> 5220.2542 | AH3: =AF3*E3-AG3 -> 0 | AI3: =IF(E3="",0,H3) -> 128166.67 | AJ3: =IFERROR((VLOOKUP(B3,'Suivi 31.12.25'!$B$1:$BF$38,36,FALSE())),0) -> 32041.667 | AK3: =AI3*E3-AJ3 -> 0 | AO3: =IF(E3=0,0,AI3-AJ3-AK3) -> 96125 | AP3: =IF(E3=0,0,AF3-AG3-AH3) -> 15660.763 | AQ3: =IF(E3="","",+AF3/AI3) -> 0.16292081 | AR3: =IF(S3="",M3*E3,S3*E3) -> 20640.833 | AS3: =IFERROR((VLOOKUP(B3,'SUIVI 31.12.24 ALTONEO'!$B$1:$BF$38,45,FALSE())),0) -> 0 | AT3: =+AR3-AS3 -> 20640.833 | AU3: =+L3*E3 -> 1957.0375 | AV3: =IFERROR((VLOOKUP(B3,'SUIVI 31.12.24 ALTONEO'!$B$1:$BF$38,48,FALSE())),0) -> 0 | AW3: =+AU3-AV3 -> 1957.0375 | AX3: =IF(P3="",J3*E3,P3-Z3) -> 1922.5 | AY3: =IFERROR((VLOOKUP(B3,'SUIVI 31.12.24 ALTONEO'!$B$1:$BF$38,51,FALSE())),0) -> 0 | AZ3: =+AX3-AY3 -> 1922.5 | BA3: =IF(Q3="",K3*E3,Q3-AB3) -> 801.04167 | BB3: =IFERROR((VLOOKUP(B3,'SUIVI 31.12.24 ALTONEO'!$B$1:$BF$38,54,FALSE())),0) -> 0 | BC3: =+BA3-BB3 -> 801.04167 | BD3: =+E3*N3 -> 1500 | BE3: =IFERROR((VLOOKUP(B3,'SUIVI 31.12.24 ALTONEO'!$B$1:$BF$38,57,FALSE())),0) -> 0
B4: Projet Moulineuf / Jouie Rouessé-Vassé | C4: non | D4: 1.1 Administratif validé prêt à ouvrir | E4: =VLOOKUP(D4,'% avancement'!$A$4:$B$17,2,FALSE()) -> 0.25 | F4: 146083.33 | G4: 7500 | H4: =F4+G4-I4 -> 148583.33 | I4: 5000 | J4: =(F4+G4-I4)*0.06 -> 8915 | K4: =(F4+G4-I4)*0.025 -> 3714.5833 | L4: 7828.15 | M4: =(F4+G4)*0.62 -> 95221.667 | N4: 6000 | U4: =IF(C4="oui","",(H4+I4)*E4) -> 38395.833 | W4: =IF(O4="",0,(1-E4)*O4) -> 0 | X4: =IF(O4="",I4*(E4),0) -> 1250 | Y4: =IF(P4="",+H4*6%*E4,0) -> 2228.75 | Z4: =IF(P4="",0,P4*(1-E4)) -> 0 | AA4: =IF(Q4="",+H4*2.5%*E4,0) -> 928.64583 | AB4: =IF(Q4="",0,Q4*(1-E4)) -> 0 | AC4: =IF(R4="",+L4*E4,(1-E4)*R4) -> 1957.0375 | AD4: =IF(S4="",M4*E4,S4*E4) -> 23805.417 | AF4: =IF(E4="",0,+H4-J4-K4-L4-M4-N4) -> 26903.933 | AG4: =IFERROR((VLOOKUP(B4,'Suivi 31.12.25'!$B$1:$BF$38,33,FALSE())),0) -> 0 | AH4: =AF4*E4-AG4 -> 6725.9833 | AI4: =IF(E4="",0,H4) -> 148583.33 | AJ4: =IFERROR((VLOOKUP(B4,'Suivi 31.12.25'!$B$1:$BF$38,36,FALSE())),0) -> 0 | AK4: =AI4*E4-AJ4 -> 37145.833 | AO4: =IF(E4=0,0,AI4-AJ4-AK4) -> 111437.5 | AP4: =IF(E4=0,0,AF4-AG4-AH4) -> 20177.95 | AQ4: =IF(E4="","",+AF4/AI4) -> 0.18106966 | AR4: =IF(S4="",M4*E4,S4*E4) -> 23805.417 | AS4: =IFERROR((VLOOKUP(B4,'SUIVI 31.12.24 ALTONEO'!$B$1:$BF$38,45,FALSE())),0) -> 0 | AT4: =+AR4-AS4 -> 23805.417 | AU4: =+L4*E4 -> 1957.0375 | AV4: =IFERROR((VLOOKUP(B4,'SUIVI 31.12.24 ALTONEO'!$B$1:$BF$38,48,FALSE())),0) -> 0 | AW4: =+AU4-AV4 -> 1957.0375 | AX4: =IF(P4="",J4*E4,P4-Z4) -> 2228.75 | AY4: =IFERROR((VLOOKUP(B4,'SUIVI 31.12.24 ALTONEO'!$B$1:$BF$38,51,FALSE())),0) -> 0 | AZ4: =+AX4-AY4 -> 2228.75 | BA4: =IF(Q4="",K4*E4,Q4-AB4) -> 928.64583 | BB4: =IFERROR((VLOOKUP(B4,'SUIVI 31.12.24 ALTONEO'!$B$1:$BF$38,54,FALSE())),0) -> 0 | BC4: =+BA4-BB4 -> 928.64583 | BD4: =+E4*N4 -> 1500 | BE4: =IFERROR((VLOOKUP(B4,'SUIVI 31.12.24 ALTONEO'!$B$1:$BF$38,57,FALSE())),0) -> 0
B5: Projet Charlong / Vivoin | C5: non | D5: 1.1 Administratif validé prêt à ouvrir | E5: =VLOOKUP(D5,'% avancement'!$A$4:$B$17,2,FALSE()) -> 0.25 | F5: 110916.67 | G5: 7500 | H5: =F5+G5-I5 -> 113416.67 | I5: 5000 | J5: =(F5+G5-I5)*0.06 -> 6805 | K5: =(F5+G5-I5)*0.025 -> 2835.4167 | L5: 7828.15 | M5: =(F5+G5)*0.62 -> 73418.333 | N5: 6000 | U5: =IF(C5="oui","",(H5+I5)*E5) -> 29604.167 | W5: =IF(O5="",0,(1-E5)*O5) -> 0 | X5: =IF(O5="",I5*(E5),0) -> 1250 | Y5: =IF(P5="",+H5*6%*E5,0) -> 1701.25 | Z5: =IF(P5="",0,P5*(1-E5)) -> 0 | AA5: =IF(Q5="",+H5*2.5%*E5,0) -> 708.85417 | AB5: =IF(Q5="",0,Q5*(1-E5)) -> 0 | AC5: =IF(R5="",+L5*E5,(1-E5)*R5) -> 1957.0375 | AD5: =IF(S5="",M5*E5,S5*E5) -> 18354.583 | AF5: =IF(E5="",0,+H5-J5-K5-L5-M5-N5) -> 16529.767 | AG5: =IFERROR((VLOOKUP(B5,'Suivi 31.12.25'!$B$1:$BF$38,33,FALSE())),0) -> 0 | AH5: =AF5*E5-AG5 -> 4132.4417 | AI5: =IF(E5="",0,H5) -> 113416.67 | AJ5: =IFERROR((VLOOKUP(B5,'Suivi 31.12.25'!$B$1:$BF$38,36,FALSE())),0) -> 0 | AK5: =AI5*E5-AJ5 -> 28354.167 | AO5: =IF(E5=0,0,AI5-AJ5-AK5) -> 85062.5 | AP5: =IF(E5=0,0,AF5-AG5-AH5) -> 12397.325 | AQ5: =IF(E5="","",+AF5/AI5) -> 0.14574372 | AR5: =IF(S5="",M5*E5,S5*E5) -> 18354.583 | AS5: =IFERROR((VLOOKUP(B5,'SUIVI 31.12.24 ALTONEO'!$B$1:$BF$38,45,FALSE())),0) -> 0 | AT5: =+AR5-AS5 -> 18354.583 | AU5: =+L5*E5 -> 1957.0375 | AV5: =IFERROR((VLOOKUP(B5,'SUIVI 31.12.24 ALTONEO'!$B$1:$BF$38,48,FALSE())),0) -> 0 | AW5: =+AU5-AV5 -> 1957.0375 | AX5: =IF(P5="",J5*E5,P5-Z5) -> 1701.25 | AY5: =IFERROR((VLOOKUP(B5,'SUIVI 31.12.24 ALTONEO'!$B$1:$BF$38,51,FALSE())),0) -> 0 | AZ5: =+AX5-AY5 -> 1701.25 | BA5: =IF(Q5="",K5*E5,Q5-AB5) -> 708.85417 | BB5: =IFERROR((VLOOKUP(B5,'SUIVI 31.12.24 ALTONEO'!$B$1:$BF$38,54,FALSE())),0) -> 0 | BC5: =+BA5-BB5 -> 708.85417 | BD5: =+E5*N5 -> 1500 | BE5: =IFERROR((VLOOKUP(B5,'SUIVI 31.12.24 ALTONEO'!$B$1:$BF$38,57,FALSE())),0) -> 0
B6: Projet Macé / Vion | C6: non | D6: 1.1 Administratif validé prêt à ouvrir | E6: =VLOOKUP(D6,'% avancement'!$A$4:$B$17,2,FALSE()) -> 0.25 | F6: 98166.667 | G6: 7500 | H6: =F6+G6-I6 -> 100666.67 | I6: 5000 | J6: =(F6+G6-I6)*0.06 -> 6040 | K6: =(F6+G6-I6)*0.025 -> 2516.6667 | L6: 7828.15 | M6: =(F6+G6)*0.62 -> 65513.333 | N6: 6000 | U6: =IF(C6="oui","",(H6+I6)*E6) -> 26416.667 | W6: =IF(O6="",0,(1-E6)*O6) -> 0 | X6: =IF(O6="",I6*(E6),0) -> 1250 | Y6: =IF(P6="",+H6*6%*E6,0) -> 1510 | Z6: =IF(P6="",0,P6*(1-E6)) -> 0 | AA6: =IF(Q6="",+H6*2.5%*E6,0) -> 629.16667 | AB6: =IF(Q6="",0,Q6*(1-E6)) -> 0 | AC6: =IF(R6="",+L6*E6,(1-E6)*R6) -> 1957.0375 | AD6: =IF(S6="",M6*E6,S6*E6) -> 16378.333 | AF6: =IF(E6="",0,+H6-J6-K6-L6-M6-N6) -> 12768.517 | AG6: =IFERROR((VLOOKUP(B6,'Suivi 31.12.25'!$B$1:$BF$38,33,FALSE())),0) -> 0 | AH6: =AF6*E6-AG6 -> 3192.1292 | AI6: =IF(E6="",0,H6) -> 100666.67 | AJ6: =IFERROR((VLOOKUP(B6,'Suivi 31.12.25'!$B$1:$BF$38,36,FALSE())),0) -> 0 | AK6: =AI6*E6-AJ6 -> 25166.667 | AO6: =IF(E6=0,0,AI6-AJ6-AK6) -> 75500 | AP6: =IF(E6=0,0,AF6-AG6-AH6) -> 9576.3875 | AQ6: =IF(E6="","",+AF6/AI6) -> 0.12683957 | AR6: =IF(S6="",M6*E6,S6*E6) -> 16378.333 | AS6: =IFERROR((VLOOKUP(B6,'SUIVI 31.12.24 ALTONEO'!$B$1:$BF$38,45,FALSE())),0) -> 0 | AT6: =+AR6-AS6 -> 16378.333 | AU6: =+L6*E6 -> 1957.0375 | AV6: =IFERROR((VLOOKUP(B6,'SUIVI 31.12.24 ALTONEO'!$B$1:$BF$38,48,FALSE())),0) -> 0 | AW6: =+AU6-AV6 -> 1957.0375 | AX6: =IF(P6="",J6*E6,P6-Z6) -> 1510 | AY6: =IFERROR((VLOOKUP(B6,'SUIVI 31.12.24 ALTONEO'!$B$1:$BF$38,51,FALSE())),0) -> 0 | AZ6: =+AX6-AY6 -> 1510 | BA6: =IF(Q6="",K6*E6,Q6-AB6) -> 629.16667 | BB6: =IFERROR((VLOOKUP(B6,'SUIVI 31.12.24 ALTONEO'!$B$1:$BF$38,54,FALSE())),0) -> 0 | BC6: =+BA6-BB6 -> 629.16667 | BD6: =+E6*N6 -> 1500 | BE6: =IFERROR((VLOOKUP(B6,'SUIVI 31.12.24 ALTONEO'!$B$1:$BF$38,57,FALSE())),0) -> 0
B7: Projet Serafin / Serafin Changé | C7: non | D7: 1.1 Administratif validé prêt à ouvrir | E7: =VLOOKUP(D7,'% avancement'!$A$4:$B$17,2,FALSE()) -> 0.25 | F7: 111416.67 | G7: 7500 | H7: =F7+G7-I7 -> 113916.67 | I7: 5000 | J7: =(F7+G7-I7)*0.06 -> 6835 | K7: =(F7+G7-I7)*0.025 -> 2847.9167 | L7: 7828.15 | M7: =(F7+G7)*0.62 -> 73728.333 | N7: 6000 | U7: =IF(C7="oui","",(H7+I7)*E7) -> 29729.167 | W7: =IF(O7="",0,(1-E7)*O7) -> 0 | X7: =IF(O7="",I7*(E7),0) -> 1250 | Y7: =IF(P7="",+H7*6%*E7,0) -> 1708.75 | Z7: =IF(P7="",0,P7*(1-E7)) -> 0 | AA7: =IF(Q7="",+H7*2.5%*E7,0) -> 711.97917 | AB7: =IF(Q7="",0,Q7*(1-E7)) -> 0 | AC7: =IF(R7="",+L7*E7,(1-E7)*R7) -> 1957.0375 | AD7: =IF(S7="",M7*E7,S7*E7) -> 18432.083 | AF7: =IF(E7="",0,+H7-J7-K7-L7-M7-N7) -> 16677.267 | AG7: =IFERROR((VLOOKUP(B7,'Suivi 31.12.25'!$B$1:$BF$38,33,FALSE())),0) -> 0 | AH7: =AF7*E7-AG7 -> 4169.3167 | AI7: =IF(E7="",0,H7) -> 113916.67 | AJ7: =IFERROR((VLOOKUP(B7,'Suivi 31.12.25'!$B$1:$BF$38,36,FALSE())),0) -> 0 | AK7: =AI7*E7-AJ7 -> 28479.167 | AO7: =IF(E7=0,0,AI7-AJ7-AK7) -> 85437.5 | AP7: =IF(E7=0,0,AF7-AG7-AH7) -> 12507.95 | AQ7: =IF(E7="","",+AF7/AI7) -> 0.14639883 | AR7: =IF(S7="",M7*E7,S7*E7) -> 18432.083 | AS7: =IFERROR((VLOOKUP(B7,'SUIVI 31.12.24 ALTONEO'!$B$1:$BF$38,45,FALSE())),0) -> 0 | AT7: =+AR7-AS7 -> 18432.083 | AU7: =+L7*E7 -> 1957.0375 | AV7: =IFERROR((VLOOKUP(B7,'SUIVI 31.12.24 ALTONEO'!$B$1:$BF$38,48,FALSE())),0) -> 0 | AW7: =+AU7-AV7 -> 1957.0375 | AX7: =IF(P7="",J7*E7,P7-Z7) -> 1708.75 | AY7: =IFERROR((VLOOKUP(B7,'SUIVI 31.12.24 ALTONEO'!$B$1:$BF$38,51,FALSE())),0) -> 0 | AZ7: =+AX7-AY7 -> 1708.75 | BA7: =IF(Q7="",K7*E7,Q7-AB7) -> 711.97917 | BB7: =IFERROR((VLOOKUP(B7,'SUIVI 31.12.24 ALTONEO'!$B$1:$BF$38,54,FALSE())),0) -> 0 | BC7: =+BA7-BB7 -> 711.97917 | BD7: =+E7*N7 -> 1500 | BE7: =IFERROR((VLOOKUP(B7,'SUIVI 31.12.24 ALTONEO'!$B$1:$BF$38,57,FALSE())),0) -> 0
B8: Projet Tekougom / Bonnétable | C8: non | D8: 1.1 Administratif validé prêt à ouvrir | E8: =VLOOKUP(D8,'% avancement'!$A$4:$B$17,2,FALSE()) -> 0.25 | F8: 115666.67 | G8: 7500 | H8: =F8+G8-I8 -> 118166.67 | I8: 5000 | J8: =(F8+G8-I8)*0.06 -> 7090 | K8: =(F8+G8-I8)*0.025 -> 2954.1667 | L8: 7828.15 | M8: =(F8+G8)*0.62 -> 76363.333 | N8: 6000 | U8: =IF(C8="oui","",(H8+I8)*E8) -> 30791.667 | W8: =IF(O8="",0,(1-E8)*O8) -> 0 | X8: =IF(O8="",I8*(E8),0) -> 1250 | Y8: =IF(P8="",+H8*6%*E8,0) -> 1772.5 | Z8: =IF(P8="",0,P8*(1-E8)) -> 0 | AA8: =IF(Q8="",+H8*2.5%*E8,0) -> 738.54167 | AB8: =IF(Q8="",0,Q8*(1-E8)) -> 0 | AC8: =IF(R8="",+L8*E8,(1-E8)*R8) -> 1957.0375 | AD8: =IF(S8="",M8*E8,S8*E8) -> 19090.833 | AF8: =IF(E8="",0,+H8-J8-K8-L8-M8-N8) -> 17931.017 | AG8: =IFERROR((VLOOKUP(B8,'Suivi 31.12.25'!$B$1:$BF$38,33,FALSE())),0) -> 0 | AH8: =AF8*E8-AG8 -> 4482.7542 | AI8: =IF(E8="",0,H8) -> 118166.67 | AJ8: =IFERROR((VLOOKUP(B8,'Suivi 31.12.25'!$B$1:$BF$38,36,FALSE())),0) -> 0 | AK8: =AI8*E8-AJ8 -> 29541.667 | AO8: =IF(E8=0,0,AI8-AJ8-AK8) -> 88625 | AP8: =IF(E8=0,0,AF8-AG8-AH8) -> 13448.263 | AQ8: =IF(E8="","",+AF8/AI8) -> 0.15174344 | AR8: =IF(S8="",M8*E8,S8*E8) -> 19090.833 | AS8: =IFERROR((VLOOKUP(B8,'SUIVI 31.12.24 ALTONEO'!$B$1:$BF$38,45,FALSE())),0) -> 0 | AT8: =+AR8-AS8 -> 19090.833 | AU8: =+L8*E8 -> 1957.0375 | AV8: =IFERROR((VLOOKUP(B8,'SUIVI 31.12.24 ALTONEO'!$B$1:$BF$38,48,FALSE())),0) -> 0 | AW8: =+AU8-AV8 -> 1957.0375 | AX8: =IF(P8="",J8*E8,P8-Z8) -> 1772.5 | AY8: =IFERROR((VLOOKUP(B8,'SUIVI 31.12.24 ALTONEO'!$B$1:$BF$38,51,FALSE())),0) -> 0 | AZ8: =+AX8-AY8 -> 1772.5 | BA8: =IF(Q8="",K8*E8,Q8-AB8) -> 738.54167 | BB8: =IFERROR((VLOOKUP(B8,'SUIVI 31.12.24 ALTONEO'!$B$1:$BF$38,54,FALSE())),0) -> 0 | BC8: =+BA8-BB8 -> 738.54167 | BD8: =+E8*N8 -> 1500 | BE8: =IFERROR((VLOOKUP(B8,'SUIVI 31.12.24 ALTONEO'!$B$1:$BF$38,57,FALSE())),0) -> 0
B9: Projet Attoumani / Attoumani Voivres Lès Le Mans | C9: non | D9: 1.1 Administratif validé prêt à ouvrir | E9: =VLOOKUP(D9,'% avancement'!$A$4:$B$17,2,FALSE()) -> 0.25 | F9: 142000 | G9: 7500 | H9: =F9+G9-I9 -> 144500 | I9: 5000 | J9: =(F9+G9-I9)*0.06 -> 8670 | K9: =(F9+G9-I9)*0.025 -> 3612.5 | L9: 7828.15 | M9: =(F9+G9)*0.62 -> 92690 | N9: 6000 | U9: =IF(C9="oui","",(H9+I9)*E9) -> 37375 | W9: =IF(O9="",0,(1-E9)*O9) -> 0 | X9: =IF(O9="",I9*(E9),0) -> 1250 | Y9: =IF(P9="",+H9*6%*E9,0) -> 2167.5 | Z9: =IF(P9="",0,P9*(1-E9)) -> 0 | AA9: =IF(Q9="",+H9*2.5%*E9,0) -> 903.125 | AB9: =IF(Q9="",0,Q9*(1-E9)) -> 0 | AC9: =IF(R9="",+L9*E9,(1-E9)*R9) -> 1957.0375 | AD9: =IF(S9="",M9*E9,S9*E9) -> 23172.5 | AF9: =IF(E9="",0,+H9-J9-K9-L9-M9-N9) -> 25699.35 | AG9: =IFERROR((VLOOKUP(B9,'Suivi 31.12.25'!$B$1:$BF$38,33,FALSE())),0) -> 0 | AH9: =AF9*E9-AG9 -> 6424.8375 | AI9: =IF(E9="",0,H9) -> 144500 | AJ9: =IFERROR((VLOOKUP(B9,'Suivi 31.12.25'!$B$1:$BF$38,36,FALSE())),0) -> 0 | AK9: =AI9*E9-AJ9 -> 36125 | AO9: =IF(E9=0,0,AI9-AJ9-AK9) -> 108375 | AP9: =IF(E9=0,0,AF9-AG9-AH9) -> 19274.513 | AQ9: =IF(E9="","",+AF9/AI9) -> 0.17785017 | AR9: =IF(S9="",M9*E9,S9*E9) -> 23172.5 | AS9: =IFERROR((VLOOKUP(B9,'SUIVI 31.12.24 ALTONEO'!$B$1:$BF$38,45,FALSE())),0) -> 0 | AT9: =+AR9-AS9 -> 23172.5 | AU9: =+L9*E9 -> 1957.0375 | AV9: =IFERROR((VLOOKUP(B9,'SUIVI 31.12.24 ALTONEO'!$B$1:$BF$38,48,FALSE())),0) -> 0 | AW9: =+AU9-AV9 -> 1957.0375 | AX9: =IF(P9="",J9*E9,P9-Z9) -> 2167.5 | AY9: =IFERROR((VLOOKUP(B9,'SUIVI 31.12.24 ALTONEO'!$B$1:$BF$38,51,FALSE())),0) -> 0 | AZ9: =+AX9-AY9 -> 2167.5 | BA9: =IF(Q9="",K9*E9,Q9-AB9) -> 903.125 | BB9: =IFERROR((VLOOKUP(B9,'SUIVI 31.12.24 ALTONEO'!$B$1:$BF$38,54,FALSE())),0) -> 0 | BC9: =+BA9-BB9 -> 903.125 | BD9: =+E9*N9 -> 1500 | BE9: =IFERROR((VLOOKUP(B9,'SUIVI 31.12.24 ALTONEO'!$B$1:$BF$38,57,FALSE())),0) -> 0
B10: Projet Millard / Lebeau Crosmières | C10: non | D10: 1.1 Administratif validé prêt à ouvrir | E10: =VLOOKUP(D10,'% avancement'!$A$4:$B$17,2,FALSE()) -> 0.25 | F10: 124000 | G10: 7500 | H10: =F10+G10-I10 -> 126500 | I10: 5000 | J10: =(F10+G10-I10)*0.06 -> 7590 | K10: =(F10+G10-I10)*0.025 -> 3162.5 | L10: 7828.15 | M10: =(F10+G10)*0.62 -> 81530 | N10: 6000 | U10: =IF(C10="oui","",(H10+I10)*E10) -> 32875 | W10: =IF(O10="",0,(1-E10)*O10) -> 0 | X10: =IF(O10="",I10*(E10),0) -> 1250 | Y10: =IF(P10="",+H10*6%*E10,0) -> 1897.5 | Z10: =IF(P10="",0,P10*(1-E10)) -> 0 | AA10: =IF(Q10="",+H10*2.5%*E10,0) -> 790.625 | AB10: =IF(Q10="",0,Q10*(1-E10)) -> 0 | AC10: =IF(R10="",+L10*E10,(1-E10)*R10) -> 1957.0375 | AD10: =IF(S10="",M10*E10,S10*E10) -> 20382.5 | AF10: =IF(E10="",0,+H10-J10-K10-L10-M10-N10) -> 20389.35 | AG10: =IFERROR((VLOOKUP(B10,'Suivi 31.12.25'!$B$1:$BF$38,33,FALSE())),0) -> 0 | AH10: =AF10*E10-AG10 -> 5097.3375 | AI10: =IF(E10="",0,H10) -> 126500 | AJ10: =IFERROR((VLOOKUP(B10,'Suivi 31.12.25'!$B$1:$BF$38,36,FALSE())),0) -> 0 | AK10: =AI10*E10-AJ10 -> 31625 | AO10: =IF(E10=0,0,AI10-AJ10-AK10) -> 94875 | AP10: =IF(E10=0,0,AF10-AG10-AH10) -> 15292.013 | AQ10: =IF(E10="","",+AF10/AI10) -> 0.16118063 | AR10: =IF(S10="",M10*E10,S10*E10) -> 20382.5 | AS10: =IFERROR((VLOOKUP(B10,'SUIVI 31.12.24 ALTONEO'!$B$1:$BF$38,45,FALSE())),0) -> 0 | AT10: =+AR10-AS10 -> 20382.5 | AU10: =+L10*E10 -> 1957.0375 | AV10: =IFERROR((VLOOKUP(B10,'SUIVI 31.12.24 ALTONEO'!$B$1:$BF$38,48,FALSE())),0) -> 0 | AW10: =+AU10-AV10 -> 1957.0375 | AX10: =IF(P10="",J10*E10,P10-Z10) -> 1897.5 | AY10: =IFERROR((VLOOKUP(B10,'SUIVI 31.12.24 ALTONEO'!$B$1:$BF$38,51,FALSE())),0) -> 0 | AZ10: =+AX10-AY10 -> 1897.5 | BA10: =IF(Q10="",K10*E10,Q10-AB10) -> 790.625 | BB10: =IFERROR((VLOOKUP(B10,'SUIVI 31.12.24 ALTONEO'!$B$1:$BF$38,54,FALSE())),0) -> 0 | BC10: =+BA10-BB10 -> 790.625 | BD10: =+E10*N10 -> 1500 | BE10: =IFERROR((VLOOKUP(B10,'SUIVI 31.12.24 ALTONEO'!$B$1:$BF$38,57,FALSE())),0) -> 0
B11: Projet Touati / Touati Fyé | C11: non | D11: 1.1 Administratif validé prêt à ouvrir | E11: =VLOOKUP(D11,'% avancement'!$A$4:$B$17,2,FALSE()) -> 0.25 | F11: 125416.67 | G11: 7500 | H11: =F11+G11-I11 -> 127916.67 | I11: 5000 | J11: =(F11+G11-I11)*0.06 -> 7675 | K11: =(F11+G11-I11)*0.025 -> 3197.9167 | L11: 7828.15 | M11: =(F11+G11)*0.62 -> 82408.333 | N11: 6000 | U11: =IF(C11="oui","",(H11+I11)*E11) -> 33229.167 | W11: =IF(O11="",0,(1-E11)*O11) -> 0 | X11: =IF(O11="",I11*(E11),0) -> 1250 | Y11: =IF(P11="",+H11*6%*E11,0) -> 1918.75 | Z11: =IF(P11="",0,P11*(1-E11)) -> 0 | AA11: =IF(Q11="",+H11*2.5%*E11,0) -> 799.47917 | AB11: =IF(Q11="",0,Q11*(1-E11)) -> 0 | AC11: =IF(R11="",+L11*E11,(1-E11)*R11) -> 1957.0375 | AD11: =IF(S11="",M11*E11,S11*E11) -> 20602.083 | AF11: =IF(E11="",0,+H11-J11-K11-L11-M11-N11) -> 20807.267 | AG11: =IFERROR((VLOOKUP(B11,'Suivi 31.12.25'!$B$1:$BF$38,33,FALSE())),0) -> 5201.8167 | AH11: =AF11*E11-AG11 -> 0 | AI11: =IF(E11="",0,H11) -> 127916.67 | AJ11: =IFERROR((VLOOKUP(B11,'Suivi 31.12.25'!$B$1:$BF$38,36,FALSE())),0) -> 31979.167 | AK11: =AI11*E11-AJ11 -> 0 | AO11: =IF(E11=0,0,AI11-AJ11-AK11) -> 95937.5 | AP11: =IF(E11=0,0,AF11-AG11-AH11) -> 15605.45 | AQ11: =IF(E11="","",+AF11/AI11) -> 0.16266267 | AR11: =IF(S11="",M11*E11,S11*E11) -> 20602.083 | AS11: =IFERROR((VLOOKUP(B11,'SUIVI 31.12.24 ALTONEO'!$B$1:$BF$38,45,FALSE())),0) -> 0 | AT11: =+AR11-AS11 -> 20602.083 | AU11: =+L11*E11 -> 1957.0375 | AV11: =IFERROR((VLOOKUP(B11,'SUIVI 31.12.24 ALTONEO'!$B$1:$BF$38,48,FALSE())),0) -> 0 | AW11: =+AU11-AV11 -> 1957.0375 | AX11: =IF(P11="",J11*E11,P11-Z11) -> 1918.75 | AY11: =IFERROR((VLOOKUP(B11,'SUIVI 31.12.24 ALTONEO'!$B$1:$BF$38,51,FALSE())),0) -> 0 | AZ11: =+AX11-AY11 -> 1918.75 | BA11: =IF(Q11="",K11*E11,Q11-AB11) -> 799.47917 | BB11: =IFERROR((VLOOKUP(B11,'SUIVI 31.12.24 ALTONEO'!$B$1:$BF$38,54,FALSE())),0) -> 0 | BC11: =+BA11-BB11 -> 799.47917 | BD11: =+E11*N11 -> 1500 | BE11: =IFERROR((VLOOKUP(B11,'SUIVI 31.12.24 ALTONEO'!$B$1:$BF$38,57,FALSE())),0) -> 0
B12: Projet Chevereau / Pichard Allonnes | C12: non | D12: 1.1 Administratif validé prêt à ouvrir | E12: =VLOOKUP(D12,'% avancement'!$A$4:$B$17,2,FALSE()) -> 0.25 | F12: 113166.67 | G12: 7500 | H12: =F12+G12-I12 -> 115666.67 | I12: 5000 | J12: =(F12+G12-I12)*0.06 -> 6940 | K12: =(F12+G12-I12)*0.025 -> 2891.6667 | L12: 7828.15 | M12: =(F12+G12)*0.62 -> 74813.333 | N12: 6000 | U12: =IF(C12="oui","",(H12+I12)*E12) -> 30166.667 | W12: =IF(O12="",0,(1-E12)*O12) -> 0 | X12: =IF(O12="",I12*(E12),0) -> 1250 | Y12: =IF(P12="",+H12*6%*E12,0) -> 1735 | Z12: =IF(P12="",0,P12*(1-E12)) -> 0 | AA12: =IF(Q12="",+H12*2.5%*E12,0) -> 722.91667 | AB12: =IF(Q12="",0,Q12*(1-E12)) -> 0 | AC12: =IF(R12="",+L12*E12,(1-E12)*R12) -> 1957.0375 | AD12: =IF(S12="",M12*E12,S12*E12) -> 18703.333 | AF12: =IF(E12="",0,+H12-J12-K12-L12-M12-N12) -> 17193.517 | AG12: =IFERROR((VLOOKUP(B12,'Suivi 31.12.25'!$B$1:$BF$38,33,FALSE())),0) -> 4298.3792 | AH12: =AF12*E12-AG12 -> 0 | AI12: =IF(E12="",0,H12) -> 115666.67 | AJ12: =IFERROR((VLOOKUP(B12,'Suivi 31.12.25'!$B$1:$BF$38,36,FALSE())),0) -> 28916.667 | AK12: =AI12*E12-AJ12 -> 0 | AO12: =IF(E12=0,0,AI12-AJ12-AK12) -> 86750 | AP12: =IF(E12=0,0,AF12-AG12-AH12) -> 12895.138 | AQ12: =IF(E12="","",+AF12/AI12) -> 0.14864712 | AR12: =IF(S12="",M12*E12,S12*E12) -> 18703.333 | AS12: =IFERROR((VLOOKUP(B12,'SUIVI 31.12.24 ALTONEO'!$B$1:$BF$38,45,FALSE())),0) -> 0 | AT12: =+AR12-AS12 -> 18703.333 | AU12: =+L12*E12 -> 1957.0375 | AV12: =IFERROR((VLOOKUP(B12,'SUIVI 31.12.24 ALTONEO'!$B$1:$BF$38,48,FALSE())),0) -> 0 | AW12: =+AU12-AV12 -> 1957.0375 | AX12: =IF(P12="",J12*E12,P12-Z12) -> 1735 | AY12: =IFERROR((VLOOKUP(B12,'SUIVI 31.12.24 ALTONEO'!$B$1:$BF$38,51,FALSE())),0) -> 0 | AZ12: =+AX12-AY12 -> 1735 | BA12: =IF(Q12="",K12*E12,Q12-AB12) -> 722.91667 | BB12: =IFERROR((VLOOKUP(B12,'SUIVI 31.12.24 ALTONEO'!$B$1:$BF$38,54,FALSE())),0) -> 0 | BC12: =+BA12-BB12 -> 722.91667 | BD12: =+E12*N12 -> 1500 | BE12: =IFERROR((VLOOKUP(B12,'SUIVI 31.12.24 ALTONEO'!$B$1:$BF$38,57,FALSE())),0) -> 0
B13: Projet Mançon / Ceton | C13: non | D13: 1.1 Administratif validé prêt à ouvrir | E13: =VLOOKUP(D13,'% avancement'!$A$4:$B$17,2,FALSE()) -> 0.25 | F13: 126583.33 | G13: 7500 | H13: =F13+G13-I13 -> 129083.33 | I13: 5000 | J13: =(F13+G13-I13)*0.06 -> 7745 | K13: =(F13+G13-I13)*0.025 -> 3227.0833 | L13: 7828.15 | M13: =(F13+G13)*0.62 -> 83131.667 | N13: 6000 | U13: =IF(C13="oui","",(H13+I13)*E13) -> 33520.833 | W13: =IF(O13="",0,(1-E13)*O13) -> 0 | X13: =IF(O13="",I13*(E13),0) -> 1250 | Y13: =IF(P13="",+H13*6%*E13,0) -> 1936.25 | Z13: =IF(P13="",0,P13*(1-E13)) -> 0 | AA13: =IF(Q13="",+H13*2.5%*E13,0) -> 806.77083 | AB13: =IF(Q13="",0,Q13*(1-E13)) -> 0 | AC13: =IF(R13="",+L13*E13,(1-E13)*R13) -> 1957.0375 | AD13: =IF(S13="",M13*E13,S13*E13) -> 20782.917 | AF13: =IF(E13="",0,+H13-J13-K13-L13-M13-N13) -> 21151.433 | AG13: =IFERROR((VLOOKUP(B13,'Suivi 31.12.25'!$B$1:$BF$38,33,FALSE())),0) -> 5287.8583 | AH13: =AF13*E13-AG13 -> 0 | AI13: =IF(E13="",0,H13) -> 129083.33 | AJ13: =IFERROR((VLOOKUP(B13,'Suivi 31.12.25'!$B$1:$BF$38,36,FALSE())),0) -> 32270.833 | AK13: =AI13*E13-AJ13 -> 0 | AO13: =IF(E13=0,0,AI13-AJ13-AK13) -> 96812.5 | AP13: =IF(E13=0,0,AF13-AG13-AH13) -> 15863.575 | AQ13: =IF(E13="","",+AF13/AI13) -> 0.16385875 | AR13: =IF(S13="",M13*E13,S13*E13) -> 20782.917 | AS13: =IFERROR((VLOOKUP(B13,'SUIVI 31.12.24 ALTONEO'!$B$1:$BF$38,45,FALSE())),0) -> 0 | AT13: =+AR13-AS13 -> 20782.917 | AU13: =+L13*E13 -> 1957.0375 | AV13: =IFERROR((VLOOKUP(B13,'SUIVI 31.12.24 ALTONEO'!$B$1:$BF$38,48,FALSE())),0) -> 0 | AW13: =+AU13-AV13 -> 1957.0375 | AX13: =IF(P13="",J13*E13,P13-Z13) -> 1936.25 | AY13: =IFERROR((VLOOKUP(B13,'SUIVI 31.12.24 ALTONEO'!$B$1:$BF$38,51,FALSE())),0) -> 0 | AZ13: =+AX13-AY13 -> 1936.25 | BA13: =IF(Q13="",K13*E13,Q13-AB13) -> 806.77083 | BB13: =IFERROR((VLOOKUP(B13,'SUIVI 31.12.24 ALTONEO'!$B$1:$BF$38,54,FALSE())),0) -> 0 | BC13: =+BA13-BB13 -> 806.77083 | BD13: =+E13*N13 -> 1500 | BE13: =IFERROR((VLOOKUP(B13,'SUIVI 31.12.24 ALTONEO'!$B$1:$BF$38,57,FALSE())),0) -> 0
B14: Projet Delaunay / Blet Vaas | C14: non | D14: 1.1 Administratif validé prêt à ouvrir | E14: =VLOOKUP(D14,'% avancement'!$A$4:$B$17,2,FALSE()) -> 0.25 | F14: 115583.33 | G14: 7500 | H14: =F14+G14-I14 -> 118083.33 | I14: 5000 | J14: =(F14+G14-I14)*0.06 -> 7085 | K14: =(F14+G14-I14)*0.025 -> 2952.0833 | L14: 7828.15 | M14: =(F14+G14)*0.62 -> 76311.667 | N14: 6000 | U14: =IF(C14="oui","",(H14+I14)*E14) -> 30770.833 | W14: =IF(O14="",0,(1-E14)*O14) -> 0 | X14: =IF(O14="",I14*(E14),0) -> 1250 | Y14: =IF(P14="",+H14*6%*E14,0) -> 1771.25 | Z14: =IF(P14="",0,P14*(1-E14)) -> 0 | AA14: =IF(Q14="",+H14*2.5%*E14,0) -> 738.02083 | AB14: =IF(Q14="",0,Q14*(1-E14)) -> 0 | AC14: =IF(R14="",+L14*E14,(1-E14)*R14) -> 1957.0375 | AD14: =IF(S14="",M14*E14,S14*E14) -> 19077.917 | AF14: =IF(E14="",0,+H14-J14-K14-L14-M14-N14) -> 17906.433 | AG14: =IFERROR((VLOOKUP(B14,'Suivi 31.12.25'!$B$1:$BF$38,33,FALSE())),0) -> 4476.6083 | AH14: =AF14*E14-AG14 -> 0 | AI14: =IF(E14="",0,H14) -> 118083.33 | AJ14: =IFERROR((VLOOKUP(B14,'Suivi 31.12.25'!$B$1:$BF$38,36,FALSE())),0) -> 29520.833 | AK14: =AI14*E14-AJ14 -> 0 | AO14: =IF(E14=0,0,AI14-AJ14-AK14) -> 88562.5 | AP14: =IF(E14=0,0,AF14-AG14-AH14) -> 13429.825 | AQ14: =IF(E14="","",+AF14/AI14) -> 0.15164234 | AR14: =IF(S14="",M14*E14,S14*E14) -> 19077.917 | AS14: =IFERROR((VLOOKUP(B14,'SUIVI 31.12.24 ALTONEO'!$B$1:$BF$38,45,FALSE())),0) -> 0 | AT14: =+AR14-AS14 -> 19077.917 | AU14: =+L14*E14 -> 1957.0375 | AV14: =IFERROR((VLOOKUP(B14,'SUIVI 31.12.24 ALTONEO'!$B$1:$BF$38,48,FALSE())),0) -> 0 | AW14: =+AU14-AV14 -> 1957.0375 | AX14: =IF(P14="",J14*E14,P14-Z14) -> 1771.25 | AY14: =IFERROR((VLOOKUP(B14,'SUIVI 31.12.24 ALTONEO'!$B$1:$BF$38,51,FALSE())),0) -> 0 | AZ14: =+AX14-AY14 -> 1771.25 | BA14: =IF(Q14="",K14*E14,Q14-AB14) -> 738.02083 | BB14: =IFERROR((VLOOKUP(B14,'SUIVI 31.12.24 ALTONEO'!$B$1:$BF$38,54,FALSE())),0) -> 0 | BC14: =+BA14-BB14 -> 738.02083 | BD14: =+E14*N14 -> 1500 | BE14: =IFERROR((VLOOKUP(B14,'SUIVI 31.12.24 ALTONEO'!$B$1:$BF$38,57,FALSE())),0) -> 0
B15: Projet Partaud / Partaud Mulsanne | C15: non | D15: 6. Mise hors d'eau | E15: =VLOOKUP(D15,'% avancement'!$A$4:$B$17,2,FALSE()) -> 0.8 | F15: 108166.67 | G15: 9098.33 | H15: =F15+G15-I15 -> 112265 | I15: 5000 | J15: 7297.23 | K15: 2806.63 | L15: 7828.15 | M15: 71608.43 | N15: 6000 | O15: 5000 | P15: 7297.23 | Q15: 2806.63 | R15: 7828.15 | S15: =M15 -> 71608.43 | T15: 6000 | U15: =IF(C15="oui","",(H15+I15)*E15) -> 93812 | W15: =IF(O15="",0,(1-E15)*O15) -> 1000 | X15: =IF(O15="",I15*(E15),0) -> 0 | Y15: =IF(P15="",+H15*6%*E15,0) -> 0 | Z15: =IF(P15="",0,P15*(1-E15)) -> 1459.446 | AA15: =IF(Q15="",+H15*2.5%*E15,0) -> 0 | AB15: =IF(Q15="",0,Q15*(1-E15)) -> 561.326 | AC15: =IF(R15="",+L15*E15,(1-E15)*R15) -> 1565.63 | AD15: =IF(S15="",M15*E15,S15*E15) -> 57286.744 | AF15: =IF(E15="",0,+H15-J15-K15-L15-M15-N15) -> 16724.56 | AG15: =IFERROR((VLOOKUP(B15,'Suivi 31.12.25'!$B$1:$BF$38,33,FALSE())),0) -> 6609.824 | AH15: =AF15*E15-AG15 -> 6769.824 | AI15: =IF(E15="",0,H15) -> 112265 | AJ15: =IFERROR((VLOOKUP(B15,'Suivi 31.12.25'!$B$1:$BF$38,36,FALSE())),0) -> 44906 | AK15: =AI15*E15-AJ15 -> 44906 | AO15: =IF(E15=0,0,AI15-AJ15-AK15) -> 22453 | AP15: =IF(E15=0,0,AF15-AG15-AH15) -> 3344.912 | AQ15: =IF(E15="","",+AF15/AI15) -> 0.14897395 | AR15: =IF(S15="",M15*E15,S15*E15) -> 57286.744 | AS15: =IFERROR((VLOOKUP(B15,'SUIVI 31.12.24 ALTONEO'!$B$1:$BF$38,45,FALSE())),0) -> 0 | AT15: =+AR15-AS15 -> 57286.744 | AU15: =+L15*E15 -> 6262.52 | AV15: =IFERROR((VLOOKUP(B15,'SUIVI 31.12.24 ALTONEO'!$B$1:$BF$38,48,FALSE())),0) -> 0 | AW15: =+AU15-AV15 -> 6262.52 | AX15: =IF(P15="",J15*E15,P15-Z15) -> 5837.784 | AY15: =IFERROR((VLOOKUP(B15,'SUIVI 31.12.24 ALTONEO'!$B$1:$BF$38,51,FALSE())),0) -> 0 | AZ15: =+AX15-AY15 -> 5837.784 | BA15: =IF(Q15="",K15*E15,Q15-AB15) -> 2245.304 | BB15: =IFERROR((VLOOKUP(B15,'SUIVI 31.12.24 ALTONEO'!$B$1:$BF$38,54,FALSE())),0) -> 0 | BC15: =+BA15-BB15 -> 2245.304 | BD15: =+E15*N15 -> 4800 | BE15: =IFERROR((VLOOKUP(B15,'SUIVI 31.12.24 ALTONEO'!$B$1:$BF$38,57,FALSE())),0) -> 0
B16: Projet Protin / Subranne St Jean de la Motte | C16: non | D16: 6. Mise hors d'eau | E16: =VLOOKUP(D16,'% avancement'!$A$5:$B$17,2,FALSE()) -> 0.8 | F16: 148500 | G16: 8587.5 | H16: =F16+G16-I16 -> 152087.5 | I16: 5000 | J16: 9885.69 | K16: 3802.19 | L16: 7828.15 | M16: 102704.28 | N16: 6000 | O16: 5000 | P16: 9885.6917 | Q16: 3802.1917 | R16: 7828.15 | S16: =M16 -> 102704.28 | T16: 6000 | U16: =IF(C16="oui","",(H16+I16)*E16) -> 125670 | W16: =IF(O16="",0,(1-E16)*O16) -> 1000 | X16: =IF(O16="",I16*(E16),0) -> 0 | Y16: =IF(P16="",+H16*6%*E16,0) -> 0 | Z16: =IF(P16="",0,P16*(1-E16)) -> 1977.1383 | AA16: =IF(Q16="",+H16*2.5%*E16,0) -> 0 | AB16: =IF(Q16="",0,Q16*(1-E16)) -> 760.43833 | AC16: =IF(R16="",+L16*E16,(1-E16)*R16) -> 1565.63 | AD16: =IF(S16="",M16*E16,S16*E16) -> 82163.424 | AF16: =IF(E16="",0,+H16-J16-K16-L16-M16-N16) -> 21867.19 | AG16: =IFERROR((VLOOKUP(B16,'Suivi 31.12.25'!$B$1:$BF$38,33,FALSE())),0) -> 13045.24 | AH16: =AF16*E16-AG16 -> 4448.512 | AI16: =IF(E16="",0,H16) -> 152087.5 | AJ16: =IFERROR((VLOOKUP(B16,'Suivi 31.12.25'!$B$1:$BF$38,36,FALSE())),0) -> 91252.5 | AK16: =AI16*E16-AJ16 -> 30417.5 | AO16: =IF(E16=0,0,AI16-AJ16-AK16) -> 30417.5 | AP16: =IF(E16=0,0,AF16-AG16-AH16) -> 4373.438 | AQ16: =IF(E16="","",+AF16/AI16) -> 0.14378032 | AR16: =IF(S16="",M16*E16,S16*E16) -> 82163.424 | AS16: =IFERROR((VLOOKUP(B16,'SUIVI 31.12.24 ALTONEO'!$B$1:$BF$38,45,FALSE())),0) -> 0 | AT16: =+AR16-AS16 -> 82163.424 | AU16: =+L16*E16 -> 6262.52 | AV16: =IFERROR((VLOOKUP(B16,'SUIVI 31.12.24 ALTONEO'!$B$1:$BF$38,48,FALSE())),0) -> 0 | AW16: =+AU16-AV16 -> 6262.52 | AX16: =IF(P16="",J16*E16,P16-Z16) -> 7908.5533 | AY16: =IFERROR((VLOOKUP(B16,'SUIVI 31.12.24 ALTONEO'!$B$1:$BF$38,51,FALSE())),0) -> 0 | AZ16: =+AX16-AY16 -> 7908.5533 | BA16: =IF(Q16="",K16*E16,Q16-AB16) -> 3041.7533 | BB16: =IFERROR((VLOOKUP(B16,'SUIVI 31.12.24 ALTONEO'!$B$1:$BF$38,54,FALSE())),0) -> 0 | BC16: =+BA16-BB16 -> 3041.7533 | BD16: =+E16*N16 -> 4800 | BE16: =IFERROR((VLOOKUP(B16,'SUIVI 31.12.24 ALTONEO'!$B$1:$BF$38,57,FALSE())),0) -> 0
B17: Projet Chafiol / Chafiol Ecommoy | C17: non | D17: 9. Réception | E17: =VLOOKUP(D17,'% avancement'!$A$5:$B$17,2,FALSE()) -> 1 | F17: 121500 | G17: 10128.33 | H17: =F17+G17-I17 -> 126628.33 | I17: 5000 | J17: 8149.59 | K17: 3134.46 | L17: 7828.15 | M17: 72850.86 | N17: 6000 | O17: 5000 | P17: =J17 -> 8149.59 | Q17: =K17 -> 3134.46 | R17: =L17 -> 7828.15 | S17: =M17 -> 72850.86 | T17: 6000 | U17: =IF(C17="oui","",(H17+I17)*E17) -> 131628.33 | W17: =IF(O17="",0,(1-E17)*O17) -> 0 | X17: =IF(O17="",I17*(E17),0) -> 0 | Y17: =IF(P17="",+H17*6%*E17,0) -> 0 | Z17: =IF(P17="",0,P17*(1-E17)) -> 0 | AA17: =IF(Q17="",+H17*2.5%*E17,0) -> 0 | AB17: =IF(Q17="",0,Q17*(1-E17)) -> 0 | AC17: =IF(R17="",+L17*E17,(1-E17)*R17) -> 0 | AD17: =IF(S17="",M17*E17,S17*E17) -> 72850.86 | AF17: =IF(E17="",0,+H17-J17-K17-L17-M17-N17) -> 28665.27 | AG17: =IFERROR((VLOOKUP(B17,'Suivi 31.12.25'!$B$1:$BF$38,33,FALSE())),0) -> 21849.371 | AH17: =AF17*E17-AG17 -> 6815.8993 | AI17: =IF(E17="",0,H17) -> 126628.33 | AJ17: =IFERROR((VLOOKUP(B17,'Suivi 31.12.25'!$B$1:$BF$38,36,FALSE())),0) -> 100302.67 | AK17: =AI17*E17-AJ17 -> 26325.663 | AO17: =IF(E17=0,0,AI17-AJ17-AK17) -> 0 | AP17: =IF(E17=0,0,AF17-AG17-AH17) -> 0 | AQ17: =IF(E17="","",+AF17/AI17) -> 0.22637328 | AR17: =IF(S17="",M17*E17,S17*E17) -> 72850.86 | AS17: =IFERROR((VLOOKUP(B17,'SUIVI 31.12.24 ALTONEO'!$B$1:$BF$38,45,FALSE())),0) -> 0 | AT17: =+AR17-AS17 -> 72850.86 | AU17: =+L17*E17 -> 7828.15 | AV17: =IFERROR((VLOOKUP(B17,'SUIVI 31.12.24 ALTONEO'!$B$1:$BF$38,48,FALSE())),0) -> 0 | AW17: =+AU17-AV17 -> 7828.15 | AX17: =IF(P17="",J17*E17,P17-Z17) -> 8149.59 | AY17: =IFERROR((VLOOKUP(B17,'SUIVI 31.12.24 ALTONEO'!$B$1:$BF$38,51,FALSE())),0) -> 0 | AZ17: =+AX17-AY17 -> 8149.59 | BA17: =IF(Q17="",K17*E17,Q17-AB17) -> 3134.46 | BB17: =IFERROR((VLOOKUP(B17,'SUIVI 31.12.24 ALTONEO'!$B$1:$BF$38,54,FALSE())),0) -> 0 | BC17: =+BA17-BB17 -> 3134.46 | BD17: =+E17*N17 -> 6000 | BE17: =IFERROR((VLOOKUP(B17,'SUIVI 31.12.24 ALTONEO'!$B$1:$BF$38,57,FALSE())),0) -> 0
B18: Projet Bigaret / Cheniour St Jean de la Motte | C18: non | D18: 6. Mise hors d'eau | E18: =VLOOKUP(D18,'% avancement'!$A$5:$B$17,2,FALSE()) -> 0.8 | F18: 129333.33 | G18: 8556.67 | H18: =F18+G18-I18 -> 132890 | I18: 5000 | J18: 8637.85 | K18: 3322.25 | L18: 7828.15 | M18: 84311.97 | N18: 6000 | O18: 5000 | P18: =10365.42/1.2 -> 8637.85 | Q18: =3986.7/1.2 -> 3322.25 | R18: 7828.15 | S18: =M18 -> 84311.97 | T18: 6000 | U18: =IF(C18="oui","",(H18+I18)*E18) -> 110312 | W18: =IF(O18="",0,(1-E18)*O18) -> 1000 | X18: =IF(O18="",I18*(E18),0) -> 0 | Y18: =IF(P18="",+H18*6%*E18,0) -> 0 | Z18: =IF(P18="",0,P18*(1-E18)) -> 1727.57 | AA18: =IF(Q18="",+H18*2.5%*E18,0) -> 0 | AB18: =IF(Q18="",0,Q18*(1-E18)) -> 664.45 | AC18: =IF(R18="",+L18*E18,(1-E18)*R18) -> 1565.63 | AD18: =IF(S18="",M18*E18,S18*E18) -> 67449.576 | AF18: =IF(E18="",0,+H18-J18-K18-L18-M18-N18) -> 22789.78 | AG18: =IFERROR((VLOOKUP(B18,'Suivi 31.12.25'!$B$1:$BF$38,33,FALSE())),0) -> 13673.868 | AH18: =AF18*E18-AG18 -> 4557.956 | AI18: =IF(E18="",0,H18) -> 132890 | AJ18: =IFERROR((VLOOKUP(B18,'Suivi 31.12.25'!$B$1:$BF$38,36,FALSE())),0) -> 79734 | AK18: =AI18*E18-AJ18 -> 26578 | AO18: =IF(E18=0,0,AI18-AJ18-AK18) -> 26578 | AP18: =IF(E18=0,0,AF18-AG18-AH18) -> 4557.956 | AQ18: =IF(E18="","",+AF18/AI18) -> 0.17149357 | AR18: =IF(S18="",M18*E18,S18*E18) -> 67449.576 | AS18: =IFERROR((VLOOKUP(B18,'SUIVI 31.12.24 ALTONEO'!$B$1:$BF$38,45,FALSE())),0) -> 0 | AT18: =+AR18-AS18 -> 67449.576 | AU18: =+L18*E18 -> 6262.52 | AV18: =IFERROR((VLOOKUP(B18,'SUIVI 31.12.24 ALTONEO'!$B$1:$BF$38,48,FALSE())),0) -> 0 | AW18: =+AU18-AV18 -> 6262.52 | AX18: =IF(P18="",J18*E18,P18-Z18) -> 6910.28 | AY18: =IFERROR((VLOOKUP(B18,'SUIVI 31.12.24 ALTONEO'!$B$1:$BF$38,51,FALSE())),0) -> 0 | AZ18: =+AX18-AY18 -> 6910.28 | BA18: =IF(Q18="",K18*E18,Q18-AB18) -> 2657.8 | BB18: =IFERROR((VLOOKUP(B18,'SUIVI 31.12.24 ALTONEO'!$B$1:$BF$38,54,FALSE())),0) -> 0 | BC18: =+BA18-BB18 -> 2657.8 | BD18: =+E18*N18 -> 4800 | BE18: =IFERROR((VLOOKUP(B18,'SUIVI 31.12.24 ALTONEO'!$B$1:$BF$38,57,FALSE())),0) -> 0
B19: Projet VIPA Immo / Allonnes | C19: non | D19: 1.1 Administratif validé prêt à ouvrir | E19: =VLOOKUP(D19,'% avancement'!$A$5:$B$17,2,FALSE()) -> 0.25 | F19: =133500/1.2 -> 111250 | G19: =8900/1.2 -> 7416.6667 | H19: =F19+G19-I19 -> 118666.67 | I19: 0 | J19: 7713.33 | K19: 2966.66 | L19: 8062.99 | M19: 92253.04 | N19: 3800 | O19: 0 | P19: =J19 -> 7713.33 | Q19: =K19 -> 2966.66 | R19: =L19 -> 8062.99 | S19: =M19 -> 92253.04 | T19: 3800 | U19: =IF(C19="oui","",(H19+I19)*E19) -> 29666.667 | W19: =IF(O19="",0,(1-E19)*O19) -> 0 | X19: =IF(O19="",I19*(E19),0) -> 0 | Y19: =IF(P19="",+H19*6%*E19,0) -> 0 | Z19: =IF(P19="",0,P19*(1-E19)) -> 5784.9975 | AA19: =IF(Q19="",+H19*2.5%*E19,0) -> 0 | AB19: =IF(Q19="",0,Q19*(1-E19)) -> 2224.995 | AC19: =IF(R19="",+L19*E19,(1-E19)*R19) -> 6047.2425 | AD19: =IF(S19="",M19*E19,S19*E19) -> 23063.26 | AF19: =IF(E19="",0,+H19-J19-K19-L19-M19-N19) -> 3870.6467 | AG19: =IFERROR((VLOOKUP(B19,'Suivi 31.12.25'!$B$1:$BF$38,33,FALSE())),0) -> 0 | AH19: =AF19*E19-AG19 -> 967.66167 | AI19: =IF(E19="",0,H19) -> 118666.67 | AJ19: =IFERROR((VLOOKUP(B19,'Suivi 31.12.25'!$B$1:$BF$38,36,FALSE())),0) -> 0 | AK19: =AI19*E19-AJ19 -> 29666.667 | AO19: =IF(E19=0,0,AI19-AJ19-AK19) -> 89000 | AP19: =IF(E19=0,0,AF19-AG19-AH19) -> 2902.985 | AQ19: =IF(E19="","",+AF19/AI19) -> 0.032617809 | AR19: =IF(S19="",M19*E19,S19*E19) -> 23063.26 | AS19: =IFERROR((VLOOKUP(B19,'SUIVI 31.12.24 ALTONEO'!$B$1:$BF$38,45,FALSE())),0) -> 0 | AT19: =+AR19-AS19 -> 23063.26 | AU19: =+L19*E19 -> 2015.7475 | AV19: =IFERROR((VLOOKUP(B19,'SUIVI 31.12.24 ALTONEO'!$B$1:$BF$38,48,FALSE())),0) -> 0 | AW19: =+AU19-AV19 -> 2015.7475 | AX19: =IF(P19="",J19*E19,P19-Z19) -> 1928.3325 | AY19: =IFERROR((VLOOKUP(B19,'SUIVI 31.12.24 ALTONEO'!$B$1:$BF$38,51,FALSE())),0) -> 0 | AZ19: =+AX19-AY19 -> 1928.3325 | BA19: =IF(Q19="",K19*E19,Q19-AB19) -> 741.665 | BB19: =IFERROR((VLOOKUP(B19,'SUIVI 31.12.24 ALTONEO'!$B$1:$BF$38,54,FALSE())),0) -> 0 | BC19: =+BA19-BB19 -> 741.665 | BD19: =+E19*N19 -> 950 | BE19: =IFERROR((VLOOKUP(B19,'SUIVI 31.12.24 ALTONEO'!$B$1:$BF$38,57,FALSE())),0) -> 0
B20: Projet Cardoso / Ryckewaert Epuisay | C20: non | D20: 6. Mise hors d'eau | E20: =VLOOKUP(D20,'% avancement'!$A$5:$B$17,2,FALSE()) -> 0.8 | F20: 127750 | G20: 11092.5 | H20: =F20+G20-I20 -> 133842.5 | I20: 5000 | J20: 8659.14 | K20: 3330.44 | L20: 7828.15 | M20: 83839.7 | N20: 6000 | O20: 5000 | P20: =J20 -> 8659.14 | Q20: =K20 -> 3330.44 | R20: =L20 -> 7828.15 | S20: =M20 -> 83839.7 | T20: 6000 | U20: =IF(C20="oui","",(H20+I20)*E20) -> 111074 | W20: =IF(O20="",0,(1-E20)*O20) -> 1000 | X20: =IF(O20="",I20*(E20),0) -> 0 | Y20: =IF(P20="",+H20*6%*E20,0) -> 0 | Z20: =IF(P20="",0,P20*(1-E20)) -> 1731.828 | AA20: =IF(Q20="",+H20*2.5%*E20,0) -> 0 | AB20: =IF(Q20="",0,Q20*(1-E20)) -> 666.088 | AC20: =IF(R20="",+L20*E20,(1-E20)*R20) -> 1565.63 | AD20: =IF(S20="",M20*E20,S20*E20) -> 67071.76 | AF20: =IF(E20="",0,+H20-J20-K20-L20-M20-N20) -> 24185.07 | AG20: =IFERROR((VLOOKUP(B20,'Suivi 31.12.25'!$B$1:$BF$38,33,FALSE())),0) -> 14798.082 | AH20: =AF20*E20-AG20 -> 4549.974 | AI20: =IF(E20="",0,H20) -> 133842.5 | AJ20: =IFERROR((VLOOKUP(B20,'Suivi 31.12.25'!$B$1:$BF$38,36,FALSE())),0) -> 79930.5 | AK20: =AI20*E20-AJ20 -> 27143.5 | AO20: =IF(E20=0,0,AI20-AJ20-AK20) -> 26768.5 | AP20: =IF(E20=0,0,AF20-AG20-AH20) -> 4837.014 | AQ20: =IF(E20="","",+AF20/AI20) -> 0.18069798 | AR20: =IF(S20="",M20*E20,S20*E20) -> 67071.76 | AS20: =IFERROR((VLOOKUP(B20,'SUIVI 31.12.24 ALTONEO'!$B$1:$BF$38,45,FALSE())),0) -> 0 | AT20: =+AR20-AS20 -> 67071.76 | AU20: =+L20*E20 -> 6262.52 | AV20: =IFERROR((VLOOKUP(B20,'SUIVI 31.12.24 ALTONEO'!$B$1:$BF$38,48,FALSE())),0) -> 0 | AW20: =+AU20-AV20 -> 6262.52 | AX20: =IF(P20="",J20*E20,P20-Z20) -> 6927.312 | AY20: =IFERROR((VLOOKUP(B20,'SUIVI 31.12.24 ALTONEO'!$B$1:$BF$38,51,FALSE())),0) -> 0 | AZ20: =+AX20-AY20 -> 6927.312 | BA20: =IF(Q20="",K20*E20,Q20-AB20) -> 2664.352 | BB20: =IFERROR((VLOOKUP(B20,'SUIVI 31.12.24 ALTONEO'!$B$1:$BF$38,54,FALSE())),0) -> 0 | BC20: =+BA20-BB20 -> 2664.352 | BD20: =+E20*N20 -> 4800 | BE20: =IFERROR((VLOOKUP(B20,'SUIVI 31.12.24 ALTONEO'!$B$1:$BF$38,57,FALSE())),0) -> 0
B21: Projet Journaux / Thinard Meurcé | C21: non | D21: 5. Achèvement des murs | E21: =VLOOKUP(D21,'% avancement'!$A$5:$B$17,2,FALSE()) -> 0.6 | F21: 116416.67 | G21: 20345 | H21: =F21+G21-I21 -> 131761.67 | I21: 5000 | J21: 8564.51 | K21: 3294.04 | L21: 7828.15 | M21: 82927.75 | N21: 6000 | O21: 5000 | P21: 8564.5083 | Q21: 3294.0417 | R21: 7828.15 | S21: =M21 -> 82927.75 | T21: 6000 | U21: =IF(C21="oui","",(H21+I21)*E21) -> 82057.002 | W21: =IF(O21="",0,(1-E21)*O21) -> 2000 | X21: =IF(O21="",I21*(E21),0) -> 0 | Y21: =IF(P21="",+H21*6%*E21,0) -> 0 | Z21: =IF(P21="",0,P21*(1-E21)) -> 3425.8033 | AA21: =IF(Q21="",+H21*2.5%*E21,0) -> 0 | AB21: =IF(Q21="",0,Q21*(1-E21)) -> 1317.6167 | AC21: =IF(R21="",+L21*E21,(1-E21)*R21) -> 3131.26 | AD21: =IF(S21="",M21*E21,S21*E21) -> 49756.65 | AF21: =IF(E21="",0,+H21-J21-K21-L21-M21-N21) -> 23147.22 | AG21: =IFERROR((VLOOKUP(B21,'Suivi 31.12.25'!$B$1:$BF$38,33,FALSE())),0) -> 14388.61 | AH21: =AF21*E21-AG21 -> -500.278 | AI21: =IF(E21="",0,H21) -> 131761.67 | AJ21: =IFERROR((VLOOKUP(B21,'Suivi 31.12.25'!$B$1:$BF$38,36,FALSE())),0) -> 79057 | AK21: =AI21*E21-AJ21 -> 0.001998 | AO21: =IF(E21=0,0,AI21-AJ21-AK21) -> 52704.668 | AP21: =IF(E21=0,0,AF21-AG21-AH21) -> 9258.888 | AQ21: =IF(E21="","",+AF21/AI21) -> 0.17567491 | AR21: =IF(S21="",M21*E21,S21*E21) -> 49756.65 | AS21: =IFERROR((VLOOKUP(B21,'SUIVI 31.12.24 ALTONEO'!$B$1:$BF$38,45,FALSE())),0) -> 0 | AT21: =+AR21-AS21 -> 49756.65 | AU21: =+L21*E21 -> 4696.89 | AV21: =IFERROR((VLOOKUP(B21,'SUIVI 31.12.24 ALTONEO'!$B$1:$BF$38,48,FALSE())),0) -> 0 | AW21: =+AU21-AV21 -> 4696.89 | AX21: =IF(P21="",J21*E21,P21-Z21) -> 5138.705 | AY21: =IFERROR((VLOOKUP(B21,'SUIVI 31.12.24 ALTONEO'!$B$1:$BF$38,51,FALSE())),0) -> 0 | AZ21: =+AX21-AY21 -> 5138.705 | BA21: =IF(Q21="",K21*E21,Q21-AB21) -> 1976.425 | BB21: =IFERROR((VLOOKUP(B21,'SUIVI 31.12.24 ALTONEO'!$B$1:$BF$38,54,FALSE())),0) -> 0 | BC21: =+BA21-BB21 -> 1976.425 | BD21: =+E21*N21 -> 3600 | BE21: =IFERROR((VLOOKUP(B21,'SUIVI 31.12.24 ALTONEO'!$B$1:$BF$38,57,FALSE())),0) -> 0
B22: Projet Moreau / Moreau Montfort Le Gesnois | C22: non | D22: 6. Mise hors d'eau | E22: =VLOOKUP(D22,'% avancement'!$A$5:$B$17,2,FALSE()) -> 0.8 | F22: 142333.33 | G22: 9400 | H22: =F22+G22-I22 -> 146733.33 | I22: 5000 | J22: 9537.67 | K22: 3668.33 | L22: 7828.15 | M22: 97088.35 | N22: 6000 | O22: 5000 | P22: 9537.6667 | Q22: 3668.3333 | R22: 7828.15 | S22: =M22 -> 97088.35 | T22: 6000 | U22: =IF(C22="oui","",(H22+I22)*E22) -> 121386.66 | W22: =IF(O22="",0,(1-E22)*O22) -> 1000 | X22: =IF(O22="",I22*(E22),0) -> 0 | Y22: =IF(P22="",+H22*6%*E22,0) -> 0 | Z22: =IF(P22="",0,P22*(1-E22)) -> 1907.5333 | AA22: =IF(Q22="",+H22*2.5%*E22,0) -> 0 | AB22: =IF(Q22="",0,Q22*(1-E22)) -> 733.66667 | AC22: =IF(R22="",+L22*E22,(1-E22)*R22) -> 1565.63 | AD22: =IF(S22="",M22*E22,S22*E22) -> 77670.68 | AF22: =IF(E22="",0,+H22-J22-K22-L22-M22-N22) -> 22610.83 | AG22: =IFERROR((VLOOKUP(B22,'Suivi 31.12.25'!$B$1:$BF$38,33,FALSE())),0) -> 9864.28 | AH22: =AF22*E22-AG22 -> 8224.384 | AI22: =IF(E22="",0,H22) -> 146733.33 | AJ22: =IFERROR((VLOOKUP(B22,'Suivi 31.12.25'!$B$1:$BF$38,36,FALSE())),0) -> 58693.2 | AK22: =AI22*E22-AJ22 -> 58693.464 | AO22: =IF(E22=0,0,AI22-AJ22-AK22) -> 29346.666 | AP22: =IF(E22=0,0,AF22-AG22-AH22) -> 4522.166 | AQ22: =IF(E22="","",+AF22/AI22) -> 0.15409471 | AR22: =IF(S22="",M22*E22,S22*E22) -> 77670.68 | AS22: =IFERROR((VLOOKUP(B22,'SUIVI 31.12.24 ALTONEO'!$B$1:$BF$38,45,FALSE())),0) -> 0 | AT22: =+AR22-AS22 -> 77670.68 | AU22: =+L22*E22 -> 6262.52 | AV22: =IFERROR((VLOOKUP(B22,'SUIVI 31.12.24 ALTONEO'!$B$1:$BF$38,48,FALSE())),0) -> 0 | AW22: =+AU22-AV22 -> 6262.52 | AX22: =IF(P22="",J22*E22,P22-Z22) -> 7630.1333 | AY22: =IFERROR((VLOOKUP(B22,'SUIVI 31.12.24 ALTONEO'!$B$1:$BF$38,51,FALSE())),0) -> 0 | AZ22: =+AX22-AY22 -> 7630.1333 | BA22: =IF(Q22="",K22*E22,Q22-AB22) -> 2934.6667 | BB22: =IFERROR((VLOOKUP(B22,'SUIVI 31.12.24 ALTONEO'!$B$1:$BF$38,54,FALSE())),0) -> 0 | BC22: =+BA22-BB22 -> 2934.6667 | BD22: =+E22*N22 -> 4800 | BE22: =IFERROR((VLOOKUP(B22,'SUIVI 31.12.24 ALTONEO'!$B$1:$BF$38,57,FALSE())),0) -> 0
B23: Projet Toin / Brault Saint Remy De Sillé | C23: non | D23: 5. Achèvement des murs | E23: =VLOOKUP(D23,'% avancement'!$A$5:$B$17,2,FALSE()) -> 0.6 | F23: 109333.33 | G23: 12078.33 | H23: =F23+G23-I23 -> 116411.66 | I23: 5000 | J23: 7566.76 | K23: 2910.29 | L23: 8062.99 | M23: 70311.97 | N23: 6000 | O23: 5000 | P23: =J23 -> 7566.76 | Q23: =K23 -> 2910.29 | R23: =L23 -> 8062.99 | S23: =M23 -> 70311.97 | T23: 6000 | U23: =IF(C23="oui","",(H23+I23)*E23) -> 72846.996 | W23: =IF(O23="",0,(1-E23)*O23) -> 2000 | X23: =IF(O23="",I23*(E23),0) -> 0 | Y23: =IF(P23="",+H23*6%*E23,0) -> 0 | Z23: =IF(P23="",0,P23*(1-E23)) -> 3026.704 | AA23: =IF(Q23="",+H23*2.5%*E23,0) -> 0 | AB23: =IF(Q23="",0,Q23*(1-E23)) -> 1164.116 | AC23: =IF(R23="",+L23*E23,(1-E23)*R23) -> 3225.196 | AD23: =IF(S23="",M23*E23,S23*E23) -> 42187.182 | AF23: =IF(E23="",0,+H23-J23-K23-L23-M23-N23) -> 21559.65 | AG23: =IFERROR((VLOOKUP(B23,'Suivi 31.12.25'!$B$1:$BF$38,33,FALSE())),0) -> 5561.0992 | AH23: =AF23*E23-AG23 -> 7374.6908 | AI23: =IF(E23="",0,H23) -> 116411.66 | AJ23: =IFERROR((VLOOKUP(B23,'Suivi 31.12.25'!$B$1:$BF$38,36,FALSE())),0) -> 29102.917 | AK23: =AI23*E23-AJ23 -> 40744.079 | AO23: =IF(E23=0,0,AI23-AJ23-AK23) -> 46564.664 | AP23: =IF(E23=0,0,AF23-AG23-AH23) -> 8623.86 | AQ23: =IF(E23="","",+AF23/AI23) -> 0.18520181 | AR23: =IF(S23="",M23*E23,S23*E23) -> 42187.182 | AS23: =IFERROR((VLOOKUP(B23,'SUIVI 31.12.24 ALTONEO'!$B$1:$BF$38,45,FALSE())),0) -> 0 | AT23: =+AR23-AS23 -> 42187.182 | AU23: =+L23*E23 -> 4837.794 | AV23: =IFERROR((VLOOKUP(B23,'SUIVI 31.12.24 ALTONEO'!$B$1:$BF$38,48,FALSE())),0) -> 0 | AW23: =+AU23-AV23 -> 4837.794 | AX23: =IF(P23="",J23*E23,P23-Z23) -> 4540.056 | AY23: =IFERROR((VLOOKUP(B23,'SUIVI 31.12.24 ALTONEO'!$B$1:$BF$38,51,FALSE())),0) -> 0 | AZ23: =+AX23-AY23 -> 4540.056 | BA23: =IF(Q23="",K23*E23,Q23-AB23) -> 1746.174 | BB23: =IFERROR((VLOOKUP(B23,'SUIVI 31.12.24 ALTONEO'!$B$1:$BF$38,54,FALSE())),0) -> 0 | BC23: =+BA23-BB23 -> 1746.174 | BD23: =+E23*N23 -> 3600 | BE23: =IFERROR((VLOOKUP(B23,'SUIVI 31.12.24 ALTONEO'!$B$1:$BF$38,57,FALSE())),0) -> 0
B24: =+ROWS(B3:B23) -> 21 | AO24: =IF(E24=0,0,AI24-AJ24-AK24) -> 0 | AP24: =IF(E24=0,0,AF24-AG24-AH24) -> 0
B25: Projet Ikia / La Ferté Bernard | C25: non | D25: 5. Achèvement des murs | E25: =VLOOKUP(D25,'% avancement'!$A$5:$B$17,2,FALSE()) -> 0.6 | F25: 98333.33 | G25: 6287.5 | H25: =F25+G25-I25 -> 99620.83 | I25: 5000 | J25: 6475.35 | K25: 2490.52 | L25: 8062.99 | M25: 59029.86 | N25: 6000 | O25: 5000 | T25: 6000 | U25: =IF(C25="oui","",(H25+I25)*E25) -> 62772.498 | W25: =IF(O25="",0,(1-E25)*O25) -> 2000 | X25: =IF(O25="",I25*(E25),0) -> 0 | Y25: =IF(P25="",+H25*6%*E25,0) -> 3586.3499 | Z25: =IF(P25="",0,P25*(1-E25)) -> 0 | AA25: =IF(Q25="",+H25*2.5%*E25,0) -> 1494.3125 | AB25: =IF(Q25="",0,Q25*(1-E25)) -> 0 | AC25: =IF(R25="",+L25*E25,(1-E25)*R25) -> 4837.794 | AD25: =IF(S25="",M25*E25,S25*E25) -> 35417.916 | AF25: =IF(E25="",0,+H25-J25-K25-L25-M25-N25) -> 17562.11 | AG25: =IFERROR((VLOOKUP(B25,'Suivi 31.12.25'!$B$1:$BF$38,33,FALSE())),0) -> 0 | AH25: =AF25*E25-AG25 -> 10537.266 | AI25: =IF(E25="",0,H25) -> 99620.83 | AJ25: =IFERROR((VLOOKUP(B25,'Suivi 31.12.25'!$B$40:$BF$50,36,FALSE())),0) -> 24905.208 | AK25: =AI25*E25-AJ25 -> 34867.29 | AO25: =IF(E25=0,0,AI25-AJ25-AK25) -> 39848.332 | AP25: =IF(E25=0,0,AF25-AG25-AH25) -> 7024.844 | AQ25: =IF(E25="","",+AF25/AI25) -> 0.17628954 | AR25: =IF(S25="",M25*E25,S25*E25) -> 35417.916 | AS25: =IFERROR((VLOOKUP(B25,'SUIVI 31.12.24 ALTONEO'!$B$1:$BF$38,45,FALSE())),0) -> 0 | AT25: =+AR25-AS25 -> 35417.916 | AU25: =+L25*E25 -> 4837.794 | AV25: =IFERROR((VLOOKUP(B25,'SUIVI 31.12.24 ALTONEO'!$B$1:$BF$38,48,FALSE())),0) -> 0 | AW25: =+AU25-AV25 -> 4837.794 | AX25: =IF(P25="",J25*E25,P25-Z25) -> 3885.21 | AY25: =IFERROR((VLOOKUP(B25,'SUIVI 31.12.24 ALTONEO'!$B$1:$BF$38,51,FALSE())),0) -> 0 | AZ25: =+AX25-AY25 -> 3885.21 | BA25: =IF(Q25="",K25*E25,Q25-AB25) -> 1494.312 | BB25: =IFERROR((VLOOKUP(B25,'SUIVI 31.12.24 ALTONEO'!$B$1:$BF$38,54,FALSE())),0) -> 0 | BC25: =+BA25-BB25 -> 1494.312 | BD25: =+E25*N25 -> 3600 | BE25: =IFERROR((VLOOKUP(B25,'SUIVI 31.12.24 ALTONEO'!$B$1:$BF$38,57,FALSE())),0) -> 0
B26: =+ROWS(B25:B25) -> 1 | AP26: =IF(E26=0,0,AF26-AG26-AH26) -> 0
B27: Projet Hugou / Hugou Villiers sur Loir | C27: non | D27: 7. Livraison de kits et ravalement | E27: =VLOOKUP(D27,'% avancement'!$A$5:$B$17,2,FALSE()) -> 0.95 | F27: 137916.67 | G27: 6700 | H27: =F27+G27-I27 -> 139616.67 | I27: 5000 | J27: 8377 | K27: 3490.42 | L27: 7828.15 | M27: 98793.9 | N27: 6000 | O27: 5000 | P27: 8377 | Q27: 3490.42 | T27: 6000 | U27: =IF(C27="oui","",(H27+I27)*E27) -> 137385.84 | W27: =IF(O27="",0,(1-E27)*O27) -> 250 | X27: =IF(O27="",I27*(E27),0) -> 0 | Y27: =IF(P27="",+H27*6%*E27,0) -> 0 | Z27: =IF(P27="",0,P27*(1-E27)) -> 418.85 | AA27: =IF(Q27="",+H27*2.5%*E27,0) -> 0 | AB27: =IF(Q27="",0,Q27*(1-E27)) -> 174.521 | AC27: =IF(R27="",+L27*E27,(1-E27)*R27) -> 7436.7425 | AD27: =IF(S27="",M27*E27,S27*E27) -> 93854.205 | AF27: =IF(E27="",0,+H27-J27-K27-L27-M27-N27) -> 15127.2 | AG27: =IFERROR((VLOOKUP(B27,'SUIVI 31.12.24 ALTONEO'!$B$1:$BF$38,33,FALSE())),0) -> 5997.0533 | AH27: =AF27*E27-AG27 -> 8373.7867 | AI27: =IF(E27="",0,H27) -> 139616.67 | AJ27: =IFERROR((VLOOKUP(B27,'SUIVI 31.12.24 ALTONEO'!$B$1:$BF$38,36,FALSE())),0) -> 27583.333 | AK27: =AI27*E27-AJ27 -> 105052.5 | AO27: =AI27-AJ27-AK27 -> 6980.8335 | AP27: =IF(E27=0,0,AF27-AG27-AH27) -> 756.36 | AQ27: =IF(E27="","",+AF27/AI27) -> 0.10834809 | AR27: =IF(S27="",M27*E27,S27*E27) -> 93854.205 | AS27: =IFERROR((VLOOKUP(B27,'SUIVI 31.12.24 ALTONEO'!$B$1:$BF$38,45,FALSE())),0) -> 17721.667 | AT27: =+AR27-AS27 -> 76132.538 | AU27: =+L27*E27 -> 7436.7425 | AV27: =IFERROR((VLOOKUP(B27,'SUIVI 31.12.24 ALTONEO'!$B$1:$BF$38,48,FALSE())),0) -> 1520.03 | AW27: =+AU27-AV27 -> 5916.7125 | AX27: =IF(P27="",J27*E27,P27-Z27) -> 7958.15 | AY27: =IFERROR((VLOOKUP(B27,'SUIVI 31.12.24 ALTONEO'!$B$1:$BF$38,51,FALSE())),0) -> 1655 | AZ27: =+AX27-AY27 -> 6303.15 | BA27: =IF(Q27="",K27*E27,Q27-AB27) -> 3315.899 | BB27: =IFERROR((VLOOKUP(B27,'SUIVI 31.12.24 ALTONEO'!$B$1:$BF$38,54,FALSE())),0) -> 689.58333 | BC27: =+BA27-BB27 -> 2626.3157 | BD27: =+E27*N27 -> 5700 | BE27: =IFERROR((VLOOKUP(B27,'SUIVI 31.12.24 ALTONEO'!$B$1:$BF$38,57,FALSE())),0) -> 0
A28: Sous-total | B28: =ROWS(B27:B27) -> 1
A29: Total | B29: =B26+B28 -> 2 | U29: =SUM(U3:U27) -> 1464778.7 | V29: =SUM(V3:V27) -> 0 | W29: =SUM(W3:W27) -> 11250 | X29: =SUM(X3:X27) -> 15000 | Y29: =SUM(Y3:Y27) -> 25856.35 | Z29: =SUM(Z3:Z27) -> 21459.87 | AA29: =SUM(AA3:AA27) -> 10773.479 | AB29: =SUM(AB3:AB27) -> 8267.2177 | ... AP29: =SUM(AP3:AP27) -> 226331.57 | AQ29: =+AF29/AI29 -> 0.15644855 | AR29: =SUM(AR3:AR27) -> 908195.59 | AS29: 174896.44 | AT29: =SUM(AT3:AT27) -> 890473.92 | AU29: =SUM(AU3:AU27) -> 86450.168 | AV29: =SUM(AV3:AV27) -> 1520.03 | AW29: =SUM(AW3:AW27) -> 84930.138 | AX29: =SUM(AX3:AX27) -> 89084.106 | AY29: =SUM(AY3:AY27) -> 1655 | AZ29: =SUM(AZ3:AZ28) -> 87429.106 | BA29: =SUM(BA3:BA28) -> 35231.978 | BB29: =SUM(BB3:BB27) -> 689.58333 | BC29: =SUM(BC3:BC28) -> 34542.394 | BD29: =SUM(BD3:BD28) -> 65450 | BE29: =SUM(BE3:BE28) -> 0 | BF29: =SUM(BF3:BF28) -> 0
AF30: =AF29-AG29-AH29 -> 226331.57 | AI30: =AI29-AJ29-AK29 -> 1484162.2 | AL30: =AF30-('Projection P&L'!B12*1000*1.1) -> -229363.35

Sheet Suivi 31.12.25
F1: Données prévisionnelles ou connues (à mettre à jour) | O1: Factures en compta (à mettre à jour) | U1: cut-off Chiffre d'affaires | Y1: Cut-off charges | AF1: Marges | AI1: Chiffre d'affaires HT | AL1: Frais de dossiers HT | AO1: Reste à comptabiliser | AQ1: % de marge nette | AR1: Solde compte de charges
A2: Étape ↑ | B2: Nom du projet | C2: Facture vente finale faite | D2: Statut chantier | E2: % Avancement | F2: Prix convenu (chiffre d'affaires) HT | G2: Montant avenants HT | H2: Prix actualisé HT net de SASA | I2: SASA dans le projet HT | J2: Redevances fondations | K2: Redevances Pub | L2: Honoraires MIKIT | M2: Sous-traitance MKT | N2: Honoraires courtage HT | O2: SASA HT | P2: Redevance MIKIT | Q2: Redevance Pub MIKIT | R2: Honoraires MKT | S2: Sous-traitance MKT | T2: Honoraires courtage HT | U2: FAE CA | V2: FAE dossiers assurance | W2: FAE SASA | X2: AAE SASA | Y2: Redevance MIKIT 6% FNP | Z2: Redevance MIKIT CCA | AA2: Redevance pub MIKIT 2.5% FNP | AB2: Redevance pub MIKIT CCA | AC2: Honoraires MIKIT FNP | AD2: Sous-traitance FNP MKT | AE2: Frais courtage CCA | AF2: Marge totale chantier HT | AG2: Marges constatées N-1 | AH2: Marges 2025 HT | AI2: CA Total HT | AJ2: CA constaté N-1 | AK2: CA 2025 HT | AL2: CA Total HT | AM2: CA constaté N-1 | AN2: CA 2024 HT | AO2: CA à comptabiliser € HT | AP2: marge à comptabiliser € HT | AR2: SS MKT | AS2: SS MKT N-1 | AT2: SS MKT N | AU2: Hono MKT | AV2: Hono MKT N-1 | AW2: Hono MKT N | AX2: Fond Mikit | AY2: Fond Mikit N-1 | AZ2: Fond Mikit N | BA2: Pub Mikit | BB2: Pub Mikit N-1 | BC2: Pub Mikit N | BD2: Commissions | BE2: Commissions N-1 | BF2: Commissions N
B3: Projet Péan / Lochet Saint Jean de la Motte | C3: non | D3: Ne pas prendre en compte | E3: =VLOOKUP(D3,'% avancement'!$A$4:$B$17,2,FALSE()) -> 0 | F3: 95666.667 | G3: 7500 | H3: =F3+G3-I3 -> 98166.667 | I3: 5000 | J3: =(F3+G3-I3)*0.06 -> 5890 | K3: =(F3+G3-I3)*0.025 -> 2454.1667 | L3: 7828.15 | M3: =(F3+G3)*0.62 -> 63963.333 | N3: 6000 | U3: =IF(C3="oui","",(H3+I3)*E3) -> 0 | W3: =IF(O3="",0,(1-E3)*O3) -> 0 | X3: =IF(O3="",I3*(E3),0) -> 0 | Y3: =IF(P3="",+H3*6%*E3,0) -> 0 | Z3: =IF(P3="",0,P3*(1-E3)) -> 0 | AA3: =IF(Q3="",+H3*2.5%*E3,0) -> 0 | AB3: =IF(Q3="",0,Q3*(1-E3)) -> 0 | AC3: =IF(R3="",+L3*E3,(1-E3)*R3) -> 0 | AD3: =IF(S3="",M3*E3,S3*E3) -> 0 | AF3: =IF(E3="",0,+H3-J3-K3-L3-M3-N3) -> 12031.017 | AG3: =IFERROR((VLOOKUP(B3,'SUIVI 31.12.24 ALTONEO'!$B$1:$BF$38,33,FALSE())),0) -> 0 | AH3: =AF3*E3-AG3 -> 0 | AI3: =IF(E3="",0,H3) -> 98166.667 | AJ3: =IFERROR((VLOOKUP(B3,'SUIVI 31.12.24 ALTONEO'!$B$1:$BF$38,36,FALSE())),0) -> 0 | AK3: =AI3*E3-AJ3 -> 0 | AO3: =IF(E3=0,0,AI3-AJ3-AK3) -> 0 | AP3: =IF(E3=0,0,AF3-AG3-AH3) -> 0 | AQ3: =IF(E3="","",+AF3/AI3) -> 0.12255705 | AR3: =IF(S3="",M3*E3,S3*E3) -> 0 | AS3: =IFERROR((VLOOKUP(B3,'SUIVI 31.12.24 ALTONEO'!$B$1:$BF$38,45,FALSE())),0) -> 0 | AT3: =+AR3-AS3 -> 0 | AU3: =+L3*E3 -> 0 | AV3: =IFERROR((VLOOKUP(B3,'SUIVI 31.12.24 ALTONEO'!$B$1:$BF$38,48,FALSE())),0) -> 0 | AW3: =+AU3-AV3 -> 0 | AX3: =IF(P3="",J3*E3,P3-Z3) -> 0 | AY3: =IFERROR((VLOOKUP(B3,'SUIVI 31.12.24 ALTONEO'!$B$1:$BF$38,51,FALSE())),0) -> 0 | AZ3: =+AX3-AY3 -> 0 | BA3: =IF(Q3="",K3*E3,Q3-AB3) -> 0 | BB3: =IFERROR((VLOOKUP(B3,'SUIVI 31.12.24 ALTONEO'!$B$1:$BF$38,54,FALSE())),0) -> 0 | BC3: =+BA3-BB3 -> 0 | BD3: =+E3*N3 -> 0 | BE3: =IFERROR((VLOOKUP(B3,'SUIVI 31.12.24 ALTONEO'!$B$1:$BF$38,57,FALSE())),0) -> 0
